Workbook

Sheet How to Use
B1: 🏆 FAMILY WORLD CUP CHALLENGE 2026 — Scoring Sheet
B3: HOW THIS WORKS
B4: Picks come in through the family group chat — you just transcribe them here, and everything scores automatically.
B5: Yellow cells are the only ones you ever type in. Everything else is calculated.
B7: THE TABS
B8: 1. Match Predictions — all 104 fixtures are pre-loaded (date, stage, group, teams). Type each person’s
B9: predicted score, then the actual final score in the two ACTUAL columns. Points fill in for everyone instantly.
B10: 2. Schedule — the full fixture list with venues and kickoff times (ET). Handy for the “make your picks” posts.
B11: 3. Tournament Picks — each person’s Champion / Runner-Up / 4 Semifinalists. Fill ACTUAL RESULTS up top
B12: as the tournament reaches those stages.
B13: 4. Leaderboard — fully automatic: totals, ranking, exact-score count, accuracy. Glance and post to the chat.
B15: SCORING (per match)
... B26: Rename or add players in the green name headers on Match Predictions; names flow to the other tabs automatically.

Sheet Match Predictions
A1: 🏆 MATCH PREDICTIONS — type each pick, then the actual score. Points are automatic.
A2: MATCH · ACTUAL RESULT | I2: Ewan | L2: Nana | O2: Emrys | R2: Nonno | U2: Nonna | X2: Boompa | AA2: Xavier | AD2: Autumn | AG2: River
A3: Match # | B3: Date | C3: Stage | D3: Group | E3: Home | F3: Away | G3: Act H | H3: Act A | I3: Pred H | J3: Pred A | K3: Pts | L3: Pred H | M3: Pred A | N3: Pts | O3: Pred H | P3: Pred A | Q3: Pts | R3: Pred H | S3: Pred A | T3: Pts | U3: Pred H | V3: Pred A | W3: Pts | X3: Pred H | Y3: Pred A | Z3: Pts | AA3: Pred H | AB3: Pred A | AC3: Pts | AD3: Pred H | AE3: Pred A | AF3: Pts | AG3: Pred H | AH3: Pred A | AI3: Pts | AJ3: Advancing (H/A)
A4: 1 | B4: 46184 | C4: Group Stage | D4: A | E4: Mexico | F4: South Africa | G4: 2 | H4: 0 | I4: 3 | J4: 1 | K4: =IF(OR(I4="",J4="",$G4="",$H4=""),0,IF(AND(I4=$G4,J4=$H4),8,IF(SIGN(I4-J4)=SIGN($G4-$H4),3,0))) -> 3 | L4: 2 | M4: 1 | N4: =IF(OR(L4="",M4="",$G4="",$H4=""),0,IF(AND(L4=$G4,M4=$H4),8,IF(SIGN(L4-M4)=SIGN($G4-$H4),3,0))) -> 3 | O4: 1 | P4: 0 | Q4: =IF(OR(O4="",P4="",$G4="",$H4=""),0,IF(AND(O4=$G4,P4=$H4),8,IF(SIGN(O4-P4)=SIGN($G4-$H4),3,0))) -> 3 | R4: 3 | S4: 0 | T4: =IF(OR(R4="",S4="",$G4="",$H4=""),0,IF(AND(R4=$G4,S4=$H4),8,IF(SIGN(R4-S4)=SIGN($G4-$H4),3,0))) -> 3 | W4: =IF(OR(U4="",V4="",$G4="",$H4=""),0,IF(AND(U4=$G4,V4=$H4),8,IF(SIGN(U4-V4)=SIGN($G4-$H4),3,0))) -> 0 | X4: 0 | Y4: 1 | Z4: =IF(OR(X4="",Y4="",$G4="",$H4=""),0,IF(AND(X4=$G4,Y4=$H4),8,IF(SIGN(X4-Y4)=SIGN($G4-$H4),3,0))) -> 0 | AA4: 2 | AB4: 0 | AC4: =IF(OR(AA4="",AB4="",$G4="",$H4=""),0,IF(AND(AA4=$G4,AB4=$H4),8,IF(SIGN(AA4-AB4)=SIGN($G4-$H4),3,0))) -> 8 | AD4: 2 | AE4: 0 | AF4: =IF(OR(AD4="",AE4="",$G4="",$H4=""),0,IF(AND(AD4=$G4,AE4=$H4),8,IF(SIGN(AD4-AE4)=SIGN($G4-$H4),3,0))) -> 8 | AG4: 2 | AH4: 1 | AI4: =IF(OR(AG4="",AH4="",$G4="",$H4=""),0,IF(AND(AG4=$G4,AH4=$H4),8,IF(SIGN(AG4-AH4)=SIGN($G4-$H4),3,0))) -> 3
A5: 2 | B5: 46184 | C5: Group Stage | D5: A | E5: South Korea | F5: Czechia | G5: 2 | H5: 1 | I5: 2 | J5: 1 | K5: =IF(OR(I5="",J5="",$G5="",$H5=""),0,IF(AND(I5=$G5,J5=$H5),8,IF(SIGN(I5-J5)=SIGN($G5-$H5),3,0))) -> 8 | L5: 2 | M5: 2 | N5: =IF(OR(L5="",M5="",$G5="",$H5=""),0,IF(AND(L5=$G5,M5=$H5),8,IF(SIGN(L5-M5)=SIGN($G5-$H5),3,0))) -> 0 | O5: 3 | P5: 1 | Q5: =IF(OR(O5="",P5="",$G5="",$H5=""),0,IF(AND(O5=$G5,P5=$H5),8,IF(SIGN(O5-P5)=SIGN($G5-$H5),3,0))) -> 3 | R5: 1 | S5: 2 | T5: =IF(OR(R5="",S5="",$G5="",$H5=""),0,IF(AND(R5=$G5,S5=$H5),8,IF(SIGN(R5-S5)=SIGN($G5-$H5),3,0))) -> 0 | U5: 2 | V5: 1 | W5: =IF(OR(U5="",V5="",$G5="",$H5=""),0,IF(AND(U5=$G5,V5=$H5),8,IF(SIGN(U5-V5)=SIGN($G5-$H5),3,0))) -> 8 | X5: 1 | Y5: 2 | Z5: =IF(OR(X5="",Y5="",$G5="",$H5=""),0,IF(AND(X5=$G5,Y5=$H5),8,IF(SIGN(X5-Y5)=SIGN($G5-$H5),3,0))) -> 0 | AA5: 2 | AB5: 1 | AC5: =IF(OR(AA5="",AB5="",$G5="",$H5=""),0,IF(AND(AA5=$G5,AB5=$H5),8,IF(SIGN(AA5-AB5)=SIGN($G5-$H5),3,0))) -> 8 | AD5: 1 | AE5: 1 | AF5: =IF(OR(AD5="",AE5="",$G5="",$H5=""),0,IF(AND(AD5=$G5,AE5=$H5),8,IF(SIGN(AD5-AE5)=SIGN($G5-$H5),3,0))) -> 0 | AG5: 1 | AH5: 2 | AI5: =IF(OR(AG5="",AH5="",$G5="",$H5=""),0,IF(AND(AG5=$G5,AH5=$H5),8,IF(SIGN(AG5-AH5)=SIGN($G5-$H5),3,0))) -> 0
A6: 3 | B6: 46185 | C6: Group Stage | D6: B | E6: Canada | F6: Bosnia and Herzegovina | G6: 1 | H6: 1 | I6: 2 | J6: 1 | K6: =IF(OR(I6="",J6="",$G6="",$H6=""),0,IF(AND(I6=$G6,J6=$H6),8,IF(SIGN(I6-J6)=SIGN($G6-$H6),3,0))) -> 0 | L6: 1 | M6: 1 | N6: =IF(OR(L6="",M6="",$G6="",$H6=""),0,IF(AND(L6=$G6,M6=$H6),8,IF(SIGN(L6-M6)=SIGN($G6-$H6),3,0))) -> 8 | O6: 2 | P6: 2 | Q6: =IF(OR(O6="",P6="",$G6="",$H6=""),0,IF(AND(O6=$G6,P6=$H6),8,IF(SIGN(O6-P6)=SIGN($G6-$H6),3,0))) -> 3 | R6: 1 | S6: 1 | T6: =IF(OR(R6="",S6="",$G6="",$H6=""),0,IF(AND(R6=$G6,S6=$H6),8,IF(SIGN(R6-S6)=SIGN($G6-$H6),3,0))) -> 8 | U6: 1 | V6: 0 | W6: =IF(OR(U6="",V6="",$G6="",$H6=""),0,IF(AND(U6=$G6,V6=$H6),8,IF(SIGN(U6-V6)=SIGN($G6-$H6),3,0))) -> 0 | X6: 3 | Y6: 0 | Z6: =IF(OR(X6="",Y6="",$G6="",$H6=""),0,IF(AND(X6=$G6,Y6=$H6),8,IF(SIGN(X6-Y6)=SIGN($G6-$H6),3,0))) -> 0 | AA6: 1 | AB6: 1 | AC6: =IF(OR(AA6="",AB6="",$G6="",$H6=""),0,IF(AND(AA6=$G6,AB6=$H6),8,IF(SIGN(AA6-AB6)=SIGN($G6-$H6),3,0))) -> 8 | AD6: 2 | AE6: 0 | AF6: =IF(OR(AD6="",AE6="",$G6="",$H6=""),0,IF(AND(AD6=$G6,AE6=$H6),8,IF(SIGN(AD6-AE6)=SIGN($G6-$H6),3,0))) -> 0 | AG6: 1 | AH6: 0 | AI6: =IF(OR(AG6="",AH6="",$G6="",$H6=""),0,IF(AND(AG6=$G6,AH6=$H6),8,IF(SIGN(AG6-AH6)=SIGN($G6-$H6),3,0))) -> 0
A7: 4 | B7: 46185 | C7: Group Stage | D7: D | E7: USA | F7: Paraguay | G7: 4 | H7: 1 | I7: 2 | J7: 0 | K7: =IF(OR(I7="",J7="",$G7="",$H7=""),0,IF(AND(I7=$G7,J7=$H7),8,IF(SIGN(I7-J7)=SIGN($G7-$H7),3,0))) -> 3 | L7: 2 | M7: 0 | N7: =IF(OR(L7="",M7="",$G7="",$H7=""),0,IF(AND(L7=$G7,M7=$H7),8,IF(SIGN(L7-M7)=SIGN($G7-$H7),3,0))) -> 3 | O7: 1 | P7: 2 | Q7: =IF(OR(O7="",P7="",$G7="",$H7=""),0,IF(AND(O7=$G7,P7=$H7),8,IF(SIGN(O7-P7)=SIGN($G7-$H7),3,0))) -> 0 | R7: 3 | S7: 1 | T7: =IF(OR(R7="",S7="",$G7="",$H7=""),0,IF(AND(R7=$G7,S7=$H7),8,IF(SIGN(R7-S7)=SIGN($G7-$H7),3,0))) -> 3 | U7: 2 | V7: 1 | W7: =IF(OR(U7="",V7="",$G7="",$H7=""),0,IF(AND(U7=$G7,V7=$H7),8,IF(SIGN(U7-V7)=SIGN($G7-$H7),3,0))) -> 3 | X7: 1 | Y7: 1 | Z7: =IF(OR(X7="",Y7="",$G7="",$H7=""),0,IF(AND(X7=$G7,Y7=$H7),8,IF(SIGN(X7-Y7)=SIGN($G7-$H7),3,0))) -> 0 | AA7: 2 | AB7: 1 | AC7: =IF(OR(AA7="",AB7="",$G7="",$H7=""),0,IF(AND(AA7=$G7,AB7=$H7),8,IF(SIGN(AA7-AB7)=SIGN($G7-$H7),3,0))) -> 3 | AD7: 1 | AE7: 1 | AF7: =IF(OR(AD7="",AE7="",$G7="",$H7=""),0,IF(AND(AD7=$G7,AE7=$H7),8,IF(SIGN(AD7-AE7)=SIGN($G7-$H7),3,0))) -> 0 | AG7: 2 | AH7: 1 | AI7: =IF(OR(AG7="",AH7="",$G7="",$H7=""),0,IF(AND(AG7=$G7,AH7=$H7),8,IF(SIGN(AG7-AH7)=SIGN($G7-$H7),3,0))) -> 3
A8: 5 | B8: 46186 | C8: Group Stage | D8: B | E8: Qatar | F8: Switzerland | I8: 0 | J8: 2 | K8: =IF(OR(I8="",J8="",$G8="",$H8=""),0,IF(AND(I8=$G8,J8=$H8),8,IF(SIGN(I8-J8)=SIGN($G8-$H8),3,0))) -> 0 | N8: =IF(OR(L8="",M8="",$G8="",$H8=""),0,IF(AND(L8=$G8,M8=$H8),8,IF(SIGN(L8-M8)=SIGN($G8-$H8),3,0))) -> 0 | Q8: =IF(OR(O8="",P8="",$G8="",$H8=""),0,IF(AND(O8=$G8,P8=$H8),8,IF(SIGN(O8-P8)=SIGN($G8-$H8),3,0))) -> 0 | R8: 0 | S8: 4 | T8: =IF(OR(R8="",S8="",$G8="",$H8=""),0,IF(AND(R8=$G8,S8=$H8),8,IF(SIGN(R8-S8)=SIGN($G8-$H8),3,0))) -> 0 | W8: =IF(OR(U8="",V8="",$G8="",$H8=""),0,IF(AND(U8=$G8,V8=$H8),8,IF(SIGN(U8-V8)=SIGN($G8-$H8),3,0))) -> 0 | X8: 0 | Y8: 1 | Z8: =IF(OR(X8="",Y8="",$G8="",$H8=""),0,IF(AND(X8=$G8,Y8=$H8),8,IF(SIGN(X8-Y8)=SIGN($G8-$H8),3,0))) -> 0 | AC8: =IF(OR(AA8="",AB8="",$G8="",$H8=""),0,IF(AND(AA8=$G8,AB8=$H8),8,IF(SIGN(AA8-AB8)=SIGN($G8-$H8),3,0))) -> 0 | AF8: =IF(OR(AD8="",AE8="",$G8="",$H8=""),0,IF(AND(AD8=$G8,AE8=$H8),8,IF(SIGN(AD8-AE8)=SIGN($G8-$H8),3,0))) -> 0 | AI8: =IF(OR(AG8="",AH8="",$G8="",$H8=""),0,IF(AND(AG8=$G8,AH8=$H8),8,IF(SIGN(AG8-AH8)=SIGN($G8-$H8),3,0))) -> 0
A9: 6 | B9: 46186 | C9: Group Stage | D9: C | E9: Brazil | F9: Morocco | I9: 3 | J9: 1 | K9: =IF(OR(I9="",J9="",$G9="",$H9=""),0,IF(AND(I9=$G9,J9=$H9),8,IF(SIGN(I9-J9)=SIGN($G9-$H9),3,0))) -> 0 | N9: =IF(OR(L9="",M9="",$G9="",$H9=""),0,IF(AND(L9=$G9,M9=$H9),8,IF(SIGN(L9-M9)=SIGN($G9-$H9),3,0))) -> 0 | Q9: =IF(OR(O9="",P9="",$G9="",$H9=""),0,IF(AND(O9=$G9,P9=$H9),8,IF(SIGN(O9-P9)=SIGN($G9-$H9),3,0))) -> 0 | R9: 3 | S9: 1 | T9: =IF(OR(R9="",S9="",$G9="",$H9=""),0,IF(AND(R9=$G9,S9=$H9),8,IF(SIGN(R9-S9)=SIGN($G9-$H9),3,0))) -> 0 | W9: =IF(OR(U9="",V9="",$G9="",$H9=""),0,IF(AND(U9=$G9,V9=$H9),8,IF(SIGN(U9-V9)=SIGN($G9-$H9),3,0))) -> 0 | X9: 3 | Y9: 1 | Z9: =IF(OR(X9="",Y9="",$G9="",$H9=""),0,IF(AND(X9=$G9,Y9=$H9),8,IF(SIGN(X9-Y9)=SIGN($G9-$H9),3,0))) -> 0 | AC9: =IF(OR(AA9="",AB9="",$G9="",$H9=""),0,IF(AND(AA9=$G9,AB9=$H9),8,IF(SIGN(AA9-AB9)=SIGN($G9-$H9),3,0))) -> 0 | AF9: =IF(OR(AD9="",AE9="",$G9="",$H9=""),0,IF(AND(AD9=$G9,AE9=$H9),8,IF(SIGN(AD9-AE9)=SIGN($G9-$H9),3,0))) -> 0 | AI9: =IF(OR(AG9="",AH9="",$G9="",$H9=""),0,IF(AND(AG9=$G9,AH9=$H9),8,IF(SIGN(AG9-AH9)=SIGN($G9-$H9),3,0))) -> 0
A10: 7 | B10: 46186 | C10: Group Stage | D10: C | E10: Haiti | F10: Scotland | I10: 0 | J10: 2 | K10: =IF(OR(I10="",J10="",$G10="",$H10=""),0,IF(AND(I10=$G10,J10=$H10),8,IF(SIGN(I10-J10)=SIGN($G10-$H10),3,0))) -> 0 | N10: =IF(OR(L10="",M10="",$G10="",$H10=""),0,IF(AND(L10=$G10,M10=$H10),8,IF(SIGN(L10-M10)=SIGN($G10-$H10),3,0))) -> 0 | Q10: =IF(OR(O10="",P10="",$G10="",$H10=""),0,IF(AND(O10=$G10,P10=$H10),8,IF(SIGN(O10-P10)=SIGN($G10-$H10),3,0))) -> 0 | R10: 0 | S10: 4 | T10: =IF(OR(R10="",S10="",$G10="",$H10=""),0,IF(AND(R10=$G10,S10=$H10),8,IF(SIGN(R10-S10)=SIGN($G10-$H10),3,0))) -> 0 | W10: =IF(OR(U10="",V10="",$G10="",$H10=""),0,IF(AND(U10=$G10,V10=$H10),8,IF(SIGN(U10-V10)=SIGN($G10-$H10),3,0))) -> 0 | X10: 0 | Y10: 1 | Z10: =IF(OR(X10="",Y10="",$G10="",$H10=""),0,IF(AND(X10=$G10,Y10=$H10),8,IF(SIGN(X10-Y10)=SIGN($G10-$H10),3,0))) -> 0 | AC10: =IF(OR(AA10="",AB10="",$G10="",$H10=""),0,IF(AND(AA10=$G10,AB10=$H10),8,IF(SIGN(AA10-AB10)=SIGN($G10-$H10),3,0))) -> 0 | AF10: =IF(OR(AD10="",AE10="",$G10="",$H10=""),0,IF(AND(AD10=$G10,AE10=$H10),8,IF(SIGN(AD10-AE10)=SIGN($G10-$H10),3,0))) -> 0 | AI10: =IF(OR(AG10="",AH10="",$G10="",$H10=""),0,IF(AND(AG10=$G10,AH10=$H10),8,IF(SIGN(AG10-AH10)=SIGN($G10-$H10),3,0))) -> 0
A11: 8 | B11: 46186 | C11: Group Stage | D11: D | E11: Australia | F11: Türkiye | I11: 0 | J11: 1 | K11: =IF(OR(I11="",J11="",$G11="",$H11=""),0,IF(AND(I11=$G11,J11=$H11),8,IF(SIGN(I11-J11)=SIGN($G11-$H11),3,0))) -> 0 | N11: =IF(OR(L11="",M11="",$G11="",$H11=""),0,IF(AND(L11=$G11,M11=$H11),8,IF(SIGN(L11-M11)=SIGN($G11-$H11),3,0))) -> 0 | Q11: =IF(OR(O11="",P11="",$G11="",$H11=""),0,IF(AND(O11=$G11,P11=$H11),8,IF(SIGN(O11-P11)=SIGN($G11-$H11),3,0))) -> 0 | R11: 1 | S11: 3 | T11: =IF(OR(R11="",S11="",$G11="",$H11=""),0,IF(AND(R11=$G11,S11=$H11),8,IF(SIGN(R11-S11)=SIGN($G11-$H11),3,0))) -> 0 | W11: =IF(OR(U11="",V11="",$G11="",$H11=""),0,IF(AND(U11=$G11,V11=$H11),8,IF(SIGN(U11-V11)=SIGN($G11-$H11),3,0))) -> 0 | X11: 1 | Y11: 3 | Z11: =IF(OR(X11="",Y11="",$G11="",$H11=""),0,IF(AND(X11=$G11,Y11=$H11),8,IF(SIGN(X11-Y11)=SIGN($G11-$H11),3,0))) -> 0 | AC11: =IF(OR(AA11="",AB11="",$G11="",$H11=""),0,IF(AND(AA11=$G11,AB11=$H11),8,IF(SIGN(AA11-AB11)=SIGN($G11-$H11),3,0))) -> 0 | AF11: =IF(OR(AD11="",AE11="",$G11="",$H11=""),0,IF(AND(AD11=$G11,AE11=$H11),8,IF(SIGN(AD11-AE11)=SIGN($G11-$H11),3,0))) -> 0 | AI11: =IF(OR(AG11="",AH11="",$G11="",$H11=""),0,IF(AND(AG11=$G11,AH11=$H11),8,IF(SIGN(AG11-AH11)=SIGN($G11-$H11),3,0))) -> 0
A12: 9 | B12: 46187 | C12: Group Stage | D12: E | E12: Germany | F12: Curaçao | K12: =IF(OR(I12="",J12="",$G12="",$H12=""),0,IF(AND(I12=$G12,J12=$H12),8,IF(SIGN(I12-J12)=SIGN($G12-$H12),3,0))) -> 0 | N12: =IF(OR(L12="",M12="",$G12="",$H12=""),0,IF(AND(L12=$G12,M12=$H12),8,IF(SIGN(L12-M12)=SIGN($G12-$H12),3,0))) -> 0 | Q12: =IF(OR(O12="",P12="",$G12="",$H12=""),0,IF(AND(O12=$G12,P12=$H12),8,IF(SIGN(O12-P12)=SIGN($G12-$H12),3,0))) -> 0 | R12: 7 | S12: 0 | T12: =IF(OR(R12="",S12="",$G12="",$H12=""),0,IF(AND(R12=$G12,S12=$H12),8,IF(SIGN(R12-S12)=SIGN($G12-$H12),3,0))) -> 0 | W12: =IF(OR(U12="",V12="",$G12="",$H12=""),0,IF(AND(U12=$G12,V12=$H12),8,IF(SIGN(U12-V12)=SIGN($G12-$H12),3,0))) -> 0 | X12: 3 | Y12: 0 | Z12: =IF(OR(X12="",Y12="",$G12="",$H12=""),0,IF(AND(X12=$G12,Y12=$H12),8,IF(SIGN(X12-Y12)=SIGN($G12-$H12),3,0))) -> 0 | AC12: =IF(OR(AA12="",AB12="",$G12="",$H12=""),0,IF(AND(AA12=$G12,AB12=$H12),8,IF(SIGN(AA12-AB12)=SIGN($G12-$H12),3,0))) -> 0 | AF12: =IF(OR(AD12="",AE12="",$G12="",$H12=""),0,IF(AND(AD12=$G12,AE12=$H12),8,IF(SIGN(AD12-AE12)=SIGN($G12-$H12),3,0))) -> 0 | AI12: =IF(OR(AG12="",AH12="",$G12="",$H12=""),0,IF(AND(AG12=$G12,AH12=$H12),8,IF(SIGN(AG12-AH12)=SIGN($G12-$H12),3,0))) -> 0
A13: 10 | B13: 46187 | C13: Group Stage | D13: F | E13: Netherlands | F13: Japan | K13: =IF(OR(I13="",J13="",$G13="",$H13=""),0,IF(AND(I13=$G13,J13=$H13),8,IF(SIGN(I13-J13)=SIGN($G13-$H13),3,0))) -> 0 | N13: =IF(OR(L13="",M13="",$G13="",$H13=""),0,IF(AND(L13=$G13,M13=$H13),8,IF(SIGN(L13-M13)=SIGN($G13-$H13),3,0))) -> 0 | Q13: =IF(OR(O13="",P13="",$G13="",$H13=""),0,IF(AND(O13=$G13,P13=$H13),8,IF(SIGN(O13-P13)=SIGN($G13-$H13),3,0))) -> 0 | R13: 2 | S13: 1 | T13: =IF(OR(R13="",S13="",$G13="",$H13=""),0,IF(AND(R13=$G13,S13=$H13),8,IF(SIGN(R13-S13)=SIGN($G13-$H13),3,0))) -> 0 | W13: =IF(OR(U13="",V13="",$G13="",$H13=""),0,IF(AND(U13=$G13,V13=$H13),8,IF(SIGN(U13-V13)=SIGN($G13-$H13),3,0))) -> 0 | X13: 1 | Y13: 1 | Z13: =IF(OR(X13="",Y13="",$G13="",$H13=""),0,IF(AND(X13=$G13,Y13=$H13),8,IF(SIGN(X13-Y13)=SIGN($G13-$H13),3,0))) -> 0 | AC13: =IF(OR(AA13="",AB13="",$G13="",$H13=""),0,IF(AND(AA13=$G13,AB13=$H13),8,IF(SIGN(AA13-AB13)=SIGN($G13-$H13),3,0))) -> 0 | AF13: =IF(OR(AD13="",AE13="",$G13="",$H13=""),0,IF(AND(AD13=$G13,AE13=$H13),8,IF(SIGN(AD13-AE13)=SIGN($G13-$H13),3,0))) -> 0 | AI13: =IF(OR(AG13="",AH13="",$G13="",$H13=""),0,IF(AND(AG13=$G13,AH13=$H13),8,IF(SIGN(AG13-AH13)=SIGN($G13-$H13),3,0))) -> 0
A14: 11 | B14: 46187 | C14: Group Stage | D14: E | E14: Ivory Coast | F14: Ecuador | K14: =IF(OR(I14="",J14="",$G14="",$H14=""),0,IF(AND(I14=$G14,J14=$H14),8,IF(SIGN(I14-J14)=SIGN($G14-$H14),3,0))) -> 0 | N14: =IF(OR(L14="",M14="",$G14="",$H14=""),0,IF(AND(L14=$G14,M14=$H14),8,IF(SIGN(L14-M14)=SIGN($G14-$H14),3,0))) -> 0 | Q14: =IF(OR(O14="",P14="",$G14="",$H14=""),0,IF(AND(O14=$G14,P14=$H14),8,IF(SIGN(O14-P14)=SIGN($G14-$H14),3,0))) -> 0 | T14: =IF(OR(R14="",S14="",$G14="",$H14=""),0,IF(AND(R14=$G14,S14=$H14),8,IF(SIGN(R14-S14)=SIGN($G14-$H14),3,0))) -> 0 | W14: =IF(OR(U14="",V14="",$G14="",$H14=""),0,IF(AND(U14=$G14,V14=$H14),8,IF(SIGN(U14-V14)=SIGN($G14-$H14),3,0))) -> 0 | X14: 1 | Y14: 2 | Z14: =IF(OR(X14="",Y14="",$G14="",$H14=""),0,IF(AND(X14=$G14,Y14=$H14),8,IF(SIGN(X14-Y14)=SIGN($G14-$H14),3,0))) -> 0 | AC14: =IF(OR(AA14="",AB14="",$G14="",$H14=""),0,IF(AND(AA14=$G14,AB14=$H14),8,IF(SIGN(AA14-AB14)=SIGN($G14-$H14),3,0))) -> 0 | AF14: =IF(OR(AD14="",AE14="",$G14="",$H14=""),0,IF(AND(AD14=$G14,AE14=$H14),8,IF(SIGN(AD14-AE14)=SIGN($G14-$H14),3,0))) -> 0 | AI14: =IF(OR(AG14="",AH14="",$G14="",$H14=""),0,IF(AND(AG14=$G14,AH14=$H14),8,IF(SIGN(AG14-AH14)=SIGN($G14-$H14),3,0))) -> 0
A15: 12 | B15: 46187 | C15: Group Stage | D15: F | E15: Tunisia | F15: Sweden | K15: =IF(OR(I15="",J15="",$G15="",$H15=""),0,IF(AND(I15=$G15,J15=$H15),8,IF(SIGN(I15-J15)=SIGN($G15-$H15),3,0))) -> 0 | N15: =IF(OR(L15="",M15="",$G15="",$H15=""),0,IF(AND(L15=$G15,M15=$H15),8,IF(SIGN(L15-M15)=SIGN($G15-$H15),3,0))) -> 0 | Q15: =IF(OR(O15="",P15="",$G15="",$H15=""),0,IF(AND(O15=$G15,P15=$H15),8,IF(SIGN(O15-P15)=SIGN($G15-$H15),3,0))) -> 0 | T15: =IF(OR(R15="",S15="",$G15="",$H15=""),0,IF(AND(R15=$G15,S15=$H15),8,IF(SIGN(R15-S15)=SIGN($G15-$H15),3,0))) -> 0 | W15: =IF(OR(U15="",V15="",$G15="",$H15=""),0,IF(AND(U15=$G15,V15=$H15),8,IF(SIGN(U15-V15)=SIGN($G15-$H15),3,0))) -> 0 | X15: 0 | Y15: 1 | Z15: =IF(OR(X15="",Y15="",$G15="",$H15=""),0,IF(AND(X15=$G15,Y15=$H15),8,IF(SIGN(X15-Y15)=SIGN($G15-$H15),3,0))) -> 0 | AC15: =IF(OR(AA15="",AB15="",$G15="",$H15=""),0,IF(AND(AA15=$G15,AB15=$H15),8,IF(SIGN(AA15-AB15)=SIGN($G15-$H15),3,0))) -> 0 | AF15: =IF(OR(AD15="",AE15="",$G15="",$H15=""),0,IF(AND(AD15=$G15,AE15=$H15),8,IF(SIGN(AD15-AE15)=SIGN($G15-$H15),3,0))) -> 0 | AI15: =IF(OR(AG15="",AH15="",$G15="",$H15=""),0,IF(AND(AG15=$G15,AH15=$H15),8,IF(SIGN(AG15-AH15)=SIGN($G15-$H15),3,0))) -> 0
A16: 13 | B16: 46188 | C16: Group Stage | D16: H | E16: Spain | F16: Cape Verde | K16: =IF(OR(I16="",J16="",$G16="",$H16=""),0,IF(AND(I16=$G16,J16=$H16),8,IF(SIGN(I16-J16)=SIGN($G16-$H16),3,0))) -> 0 | N16: =IF(OR(L16="",M16="",$G16="",$H16=""),0,IF(AND(L16=$G16,M16=$H16),8,IF(SIGN(L16-M16)=SIGN($G16-$H16),3,0))) -> 0 | Q16: =IF(OR(O16="",P16="",$G16="",$H16=""),0,IF(AND(O16=$G16,P16=$H16),8,IF(SIGN(O16-P16)=SIGN($G16-$H16),3,0))) -> 0 | T16: =IF(OR(R16="",S16="",$G16="",$H16=""),0,IF(AND(R16=$G16,S16=$H16),8,IF(SIGN(R16-S16)=SIGN($G16-$H16),3,0))) -> 0 | W16: =IF(OR(U16="",V16="",$G16="",$H16=""),0,IF(AND(U16=$G16,V16=$H16),8,IF(SIGN(U16-V16)=SIGN($G16-$H16),3,0))) -> 0 | X16: 3 | Y16: 0 | Z16: =IF(OR(X16="",Y16="",$G16="",$H16=""),0,IF(AND(X16=$G16,Y16=$H16),8,IF(SIGN(X16-Y16)=SIGN($G16-$H16),3,0))) -> 0 | AC16: =IF(OR(AA16="",AB16="",$G16="",$H16=""),0,IF(AND(AA16=$G16,AB16=$H16),8,IF(SIGN(AA16-AB16)=SIGN($G16-$H16),3,0))) -> 0 | AF16: =IF(OR(AD16="",AE16="",$G16="",$H16=""),0,IF(AND(AD16=$G16,AE16=$H16),8,IF(SIGN(AD16-AE16)=SIGN($G16-$H16),3,0))) -> 0 | AI16: =IF(OR(AG16="",AH16="",$G16="",$H16=""),0,IF(AND(AG16=$G16,AH16=$H16),8,IF(SIGN(AG16-AH16)=SIGN($G16-$H16),3,0))) -> 0
A17: 14 | B17: 46188 | C17: Group Stage | D17: G | E17: Belgium | F17: Egypt | K17: =IF(OR(I17="",J17="",$G17="",$H17=""),0,IF(AND(I17=$G17,J17=$H17),8,IF(SIGN(I17-J17)=SIGN($G17-$H17),3,0))) -> 0 | N17: =IF(OR(L17="",M17="",$G17="",$H17=""),0,IF(AND(L17=$G17,M17=$H17),8,IF(SIGN(L17-M17)=SIGN($G17-$H17),3,0))) -> 0 | Q17: =IF(OR(O17="",P17="",$G17="",$H17=""),0,IF(AND(O17=$G17,P17=$H17),8,IF(SIGN(O17-P17)=SIGN($G17-$H17),3,0))) -> 0 | T17: =IF(OR(R17="",S17="",$G17="",$H17=""),0,IF(AND(R17=$G17,S17=$H17),8,IF(SIGN(R17-S17)=SIGN($G17-$H17),3,0))) -> 0 | W17: =IF(OR(U17="",V17="",$G17="",$H17=""),0,IF(AND(U17=$G17,V17=$H17),8,IF(SIGN(U17-V17)=SIGN($G17-$H17),3,0))) -> 0 | X17: 3 | Y17: 2 | Z17: =IF(OR(X17="",Y17="",$G17="",$H17=""),0,IF(AND(X17=$G17,Y17=$H17),8,IF(SIGN(X17-Y17)=SIGN($G17-$H17),3,0))) -> 0 | AC17: =IF(OR(AA17="",AB17="",$G17="",$H17=""),0,IF(AND(AA17=$G17,AB17=$H17),8,IF(SIGN(AA17-AB17)=SIGN($G17-$H17),3,0))) -> 0 | AF17: =IF(OR(AD17="",AE17="",$G17="",$H17=""),0,IF(AND(AD17=$G17,AE17=$H17),8,IF(SIGN(AD17-AE17)=SIGN($G17-$H17),3,0))) -> 0 | AI17: =IF(OR(AG17="",AH17="",$G17="",$H17=""),0,IF(AND(AG17=$G17,AH17=$H17),8,IF(SIGN(AG17-AH17)=SIGN($G17-$H17),3,0))) -> 0
A18: 15 | B18: 46188 | C18: Group Stage | D18: H | E18: Saudi Arabia | F18: Uruguay | K18: =IF(OR(I18="",J18="",$G18="",$H18=""),0,IF(AND(I18=$G18,J18=$H18),8,IF(SIGN(I18-J18)=SIGN($G18-$H18),3,0))) -> 0 | N18: =IF(OR(L18="",M18="",$G18="",$H18=""),0,IF(AND(L18=$G18,M18=$H18),8,IF(SIGN(L18-M18)=SIGN($G18-$H18),3,0))) -> 0 | Q18: =IF(OR(O18="",P18="",$G18="",$H18=""),0,IF(AND(O18=$G18,P18=$H18),8,IF(SIGN(O18-P18)=SIGN($G18-$H18),3,0))) -> 0 | T18: =IF(OR(R18="",S18="",$G18="",$H18=""),0,IF(AND(R18=$G18,S18=$H18),8,IF(SIGN(R18-S18)=SIGN($G18-$H18),3,0))) -> 0 | W18: =IF(OR(U18="",V18="",$G18="",$H18=""),0,IF(AND(U18=$G18,V18=$H18),8,IF(SIGN(U18-V18)=SIGN($G18-$H18),3,0))) -> 0 | X18: 1 | Y18: 1 | Z18: =IF(OR(X18="",Y18="",$G18="",$H18=""),0,IF(AND(X18=$G18,Y18=$H18),8,IF(SIGN(X18-Y18)=SIGN($G18-$H18),3,0))) -> 0 | AC18: =IF(OR(AA18="",AB18="",$G18="",$H18=""),0,IF(AND(AA18=$G18,AB18=$H18),8,IF(SIGN(AA18-AB18)=SIGN($G18-$H18),3,0))) -> 0 | AF18: =IF(OR(AD18="",AE18="",$G18="",$H18=""),0,IF(AND(AD18=$G18,AE18=$H18),8,IF(SIGN(AD18-AE18)=SIGN($G18-$H18),3,0))) -> 0 | AI18: =IF(OR(AG18="",AH18="",$G18="",$H18=""),0,IF(AND(AG18=$G18,AH18=$H18),8,IF(SIGN(AG18-AH18)=SIGN($G18-$H18),3,0))) -> 0
A19: 16 | B19: 46188 | C19: Group Stage | D19: G | E19: Iran | F19: New Zealand | K19: =IF(OR(I19="",J19="",$G19="",$H19=""),0,IF(AND(I19=$G19,J19=$H19),8,IF(SIGN(I19-J19)=SIGN($G19-$H19),3,0))) -> 0 | N19: =IF(OR(L19="",M19="",$G19="",$H19=""),0,IF(AND(L19=$G19,M19=$H19),8,IF(SIGN(L19-M19)=SIGN($G19-$H19),3,0))) -> 0 | Q19: =IF(OR(O19="",P19="",$G19="",$H19=""),0,IF(AND(O19=$G19,P19=$H19),8,IF(SIGN(O19-P19)=SIGN($G19-$H19),3,0))) -> 0 | T19: =IF(OR(R19="",S19="",$G19="",$H19=""),0,IF(AND(R19=$G19,S19=$H19),8,IF(SIGN(R19-S19)=SIGN($G19-$H19),3,0))) -> 0 | W19: =IF(OR(U19="",V19="",$G19="",$H19=""),0,IF(AND(U19=$G19,V19=$H19),8,IF(SIGN(U19-V19)=SIGN($G19-$H19),3,0))) -> 0 | X19: 0 | Y19: 0 | Z19: =IF(OR(X19="",Y19="",$G19="",$H19=""),0,IF(AND(X19=$G19,Y19=$H19),8,IF(SIGN(X19-Y19)=SIGN($G19-$H19),3,0))) -> 0 | AC19: =IF(OR(AA19="",AB19="",$G19="",$H19=""),0,IF(AND(AA19=$G19,AB19=$H19),8,IF(SIGN(AA19-AB19)=SIGN($G19-$H19),3,0))) -> 0 | AF19: =IF(OR(AD19="",AE19="",$G19="",$H19=""),0,IF(AND(AD19=$G19,AE19=$H19),8,IF(SIGN(AD19-AE19)=SIGN($G19-$H19),3,0))) -> 0 | AI19: =IF(OR(AG19="",AH19="",$G19="",$H19=""),0,IF(AND(AG19=$G19,AH19=$H19),8,IF(SIGN(AG19-AH19)=SIGN($G19-$H19),3,0))) -> 0
A20: 17 | B20: 46189 | C20: Group Stage | D20: I | E20: France | F20: Senegal | K20: =IF(OR(I20="",J20="",$G20="",$H20=""),0,IF(AND(I20=$G20,J20=$H20),8,IF(SIGN(I20-J20)=SIGN($G20-$H20),3,0))) -> 0 | N20: =IF(OR(L20="",M20="",$G20="",$H20=""),0,IF(AND(L20=$G20,M20=$H20),8,IF(SIGN(L20-M20)=SIGN($G20-$H20),3,0))) -> 0 | Q20: =IF(OR(O20="",P20="",$G20="",$H20=""),0,IF(AND(O20=$G20,P20=$H20),8,IF(SIGN(O20-P20)=SIGN($G20-$H20),3,0))) -> 0 | T20: =IF(OR(R20="",S20="",$G20="",$H20=""),0,IF(AND(R20=$G20,S20=$H20),8,IF(SIGN(R20-S20)=SIGN($G20-$H20),3,0))) -> 0 | W20: =IF(OR(U20="",V20="",$G20="",$H20=""),0,IF(AND(U20=$G20,V20=$H20),8,IF(SIGN(U20-V20)=SIGN($G20-$H20),3,0))) -> 0 | X20: 3 | Y20: 0 | Z20: =IF(OR(X20="",Y20="",$G20="",$H20=""),0,IF(AND(X20=$G20,Y20=$H20),8,IF(SIGN(X20-Y20)=SIGN($G20-$H20),3,0))) -> 0 | AC20: =IF(OR(AA20="",AB20="",$G20="",$H20=""),0,IF(AND(AA20=$G20,AB20=$H20),8,IF(SIGN(AA20-AB20)=SIGN($G20-$H20),3,0))) -> 0 | AF20: =IF(OR(AD20="",AE20="",$G20="",$H20=""),0,IF(AND(AD20=$G20,AE20=$H20),8,IF(SIGN(AD20-AE20)=SIGN($G20-$H20),3,0))) -> 0 | AI20: =IF(OR(AG20="",AH20="",$G20="",$H20=""),0,IF(AND(AG20=$G20,AH20=$H20),8,IF(SIGN(AG20-AH20)=SIGN($G20-$H20),3,0))) -> 0
A21: 18 | B21: 46189 | C21: Group Stage | D21: I | E21: Iraq | F21: Norway | K21: =IF(OR(I21="",J21="",$G21="",$H21=""),0,IF(AND(I21=$G21,J21=$H21),8,IF(SIGN(I21-J21)=SIGN($G21-$H21),3,0))) -> 0 | N21: =IF(OR(L21="",M21="",$G21="",$H21=""),0,IF(AND(L21=$G21,M21=$H21),8,IF(SIGN(L21-M21)=SIGN($G21-$H21),3,0))) -> 0 | Q21: =IF(OR(O21="",P21="",$G21="",$H21=""),0,IF(AND(O21=$G21,P21=$H21),8,IF(SIGN(O21-P21)=SIGN($G21-$H21),3,0))) -> 0 | T21: =IF(OR(R21="",S21="",$G21="",$H21=""),0,IF(AND(R21=$G21,S21=$H21),8,IF(SIGN(R21-S21)=SIGN($G21-$H21),3,0))) -> 0 | W21: =IF(OR(U21="",V21="",$G21="",$H21=""),0,IF(AND(U21=$G21,V21=$H21),8,IF(SIGN(U21-V21)=SIGN($G21-$H21),3,0))) -> 0 | X21: 0 | Y21: 3 | Z21: =IF(OR(X21="",Y21="",$G21="",$H21=""),0,IF(AND(X21=$G21,Y21=$H21),8,IF(SIGN(X21-Y21)=SIGN($G21-$H21),3,0))) -> 0 | AC21: =IF(OR(AA21="",AB21="",$G21="",$H21=""),0,IF(AND(AA21=$G21,AB21=$H21),8,IF(SIGN(AA21-AB21)=SIGN($G21-$H21),3,0))) -> 0 | AF21: =IF(OR(AD21="",AE21="",$G21="",$H21=""),0,IF(AND(AD21=$G21,AE21=$H21),8,IF(SIGN(AD21-AE21)=SIGN($G21-$H21),3,0))) -> 0 | AI21: =IF(OR(AG21="",AH21="",$G21="",$H21=""),0,IF(AND(AG21=$G21,AH21=$H21),8,IF(SIGN(AG21-AH21)=SIGN($G21-$H21),3,0))) -> 0
A22: 19 | B22: 46189 | C22: Group Stage | D22: J | E22: Argentina | F22: Algeria | K22: =IF(OR(I22="",J22="",$G22="",$H22=""),0,IF(AND(I22=$G22,J22=$H22),8,IF(SIGN(I22-J22)=SIGN($G22-$H22),3,0))) -> 0 | L22: 3 | M22: 0 | N22: =IF(OR(L22="",M22="",$G22="",$H22=""),0,IF(AND(L22=$G22,M22=$H22),8,IF(SIGN(L22-M22)=SIGN($G22-$H22),3,0))) -> 0 | Q22: =IF(OR(O22="",P22="",$G22="",$H22=""),0,IF(AND(O22=$G22,P22=$H22),8,IF(SIGN(O22-P22)=SIGN($G22-$H22),3,0))) -> 0 | T22: =IF(OR(R22="",S22="",$G22="",$H22=""),0,IF(AND(R22=$G22,S22=$H22),8,IF(SIGN(R22-S22)=SIGN($G22-$H22),3,0))) -> 0 | W22: =IF(OR(U22="",V22="",$G22="",$H22=""),0,IF(AND(U22=$G22,V22=$H22),8,IF(SIGN(U22-V22)=SIGN($G22-$H22),3,0))) -> 0 | X22: 2 | Y22: 0 | Z22: =IF(OR(X22="",Y22="",$G22="",$H22=""),0,IF(AND(X22=$G22,Y22=$H22),8,IF(SIGN(X22-Y22)=SIGN($G22-$H22),3,0))) -> 0 | AC22: =IF(OR(AA22="",AB22="",$G22="",$H22=""),0,IF(AND(AA22=$G22,AB22=$H22),8,IF(SIGN(AA22-AB22)=SIGN($G22-$H22),3,0))) -> 0 | AF22: =IF(OR(AD22="",AE22="",$G22="",$H22=""),0,IF(AND(AD22=$G22,AE22=$H22),8,IF(SIGN(AD22-AE22)=SIGN($G22-$H22),3,0))) -> 0 | AI22: =IF(OR(AG22="",AH22="",$G22="",$H22=""),0,IF(AND(AG22=$G22,AH22=$H22),8,IF(SIGN(AG22-AH22)=SIGN($G22-$H22),3,0))) -> 0
A23: 20 | B23: 46189 | C23: Group Stage | D23: J | E23: Austria | F23: Jordan | K23: =IF(OR(I23="",J23="",$G23="",$H23=""),0,IF(AND(I23=$G23,J23=$H23),8,IF(SIGN(I23-J23)=SIGN($G23-$H23),3,0))) -> 0 | N23: =IF(OR(L23="",M23="",$G23="",$H23=""),0,IF(AND(L23=$G23,M23=$H23),8,IF(SIGN(L23-M23)=SIGN($G23-$H23),3,0))) -> 0 | Q23: =IF(OR(O23="",P23="",$G23="",$H23=""),0,IF(AND(O23=$G23,P23=$H23),8,IF(SIGN(O23-P23)=SIGN($G23-$H23),3,0))) -> 0 | T23: =IF(OR(R23="",S23="",$G23="",$H23=""),0,IF(AND(R23=$G23,S23=$H23),8,IF(SIGN(R23-S23)=SIGN($G23-$H23),3,0))) -> 0 | W23: =IF(OR(U23="",V23="",$G23="",$H23=""),0,IF(AND(U23=$G23,V23=$H23),8,IF(SIGN(U23-V23)=SIGN($G23-$H23),3,0))) -> 0 | X23: 1 | Y23: 0 | Z23: =IF(OR(X23="",Y23="",$G23="",$H23=""),0,IF(AND(X23=$G23,Y23=$H23),8,IF(SIGN(X23-Y23)=SIGN($G23-$H23),3,0))) -> 0 | AC23: =IF(OR(AA23="",AB23="",$G23="",$H23=""),0,IF(AND(AA23=$G23,AB23=$H23),8,IF(SIGN(AA23-AB23)=SIGN($G23-$H23),3,0))) -> 0 | AF23: =IF(OR(AD23="",AE23="",$G23="",$H23=""),0,IF(AND(AD23=$G23,AE23=$H23),8,IF(SIGN(AD23-AE23)=SIGN($G23-$H23),3,0))) -> 0 | AI23: =IF(OR(AG23="",AH23="",$G23="",$H23=""),0,IF(AND(AG23=$G23,AH23=$H23),8,IF(SIGN(AG23-AH23)=SIGN($G23-$H23),3,0))) -> 0
A24: 21 | B24: 46190 | C24: Group Stage | D24: K | E24: Portugal | F24: DR Congo | K24: =IF(OR(I24="",J24="",$G24="",$H24=""),0,IF(AND(I24=$G24,J24=$H24),8,IF(SIGN(I24-J24)=SIGN($G24-$H24),3,0))) -> 0 | N24: =IF(OR(L24="",M24="",$G24="",$H24=""),0,IF(AND(L24=$G24,M24=$H24),8,IF(SIGN(L24-M24)=SIGN($G24-$H24),3,0))) -> 0 | Q24: =IF(OR(O24="",P24="",$G24="",$H24=""),0,IF(AND(O24=$G24,P24=$H24),8,IF(SIGN(O24-P24)=SIGN($G24-$H24),3,0))) -> 0 | T24: =IF(OR(R24="",S24="",$G24="",$H24=""),0,IF(AND(R24=$G24,S24=$H24),8,IF(SIGN(R24-S24)=SIGN($G24-$H24),3,0))) -> 0 | W24: =IF(OR(U24="",V24="",$G24="",$H24=""),0,IF(AND(U24=$G24,V24=$H24),8,IF(SIGN(U24-V24)=SIGN($G24-$H24),3,0))) -> 0 | X24: 2 | Y24: 0 | Z24: =IF(OR(X24="",Y24="",$G24="",$H24=""),0,IF(AND(X24=$G24,Y24=$H24),8,IF(SIGN(X24-Y24)=SIGN($G24-$H24),3,0))) -> 0 | AC24: =IF(OR(AA24="",AB24="",$G24="",$H24=""),0,IF(AND(AA24=$G24,AB24=$H24),8,IF(SIGN(AA24-AB24)=SIGN($G24-$H24),3,0))) -> 0 | AF24: =IF(OR(AD24="",AE24="",$G24="",$H24=""),0,IF(AND(AD24=$G24,AE24=$H24),8,IF(SIGN(AD24-AE24)=SIGN($G24-$H24),3,0))) -> 0 | AI24: =IF(OR(AG24="",AH24="",$G24="",$H24=""),0,IF(AND(AG24=$G24,AH24=$H24),8,IF(SIGN(AG24-AH24)=SIGN($G24-$H24),3,0))) -> 0
A25: 22 | B25: 46190 | C25: Group Stage | D25: L | E25: England | F25: Croatia | K25: =IF(OR(I25="",J25="",$G25="",$H25=""),0,IF(AND(I25=$G25,J25=$H25),8,IF(SIGN(I25-J25)=SIGN($G25-$H25),3,0))) -> 0 | N25: =IF(OR(L25="",M25="",$G25="",$H25=""),0,IF(AND(L25=$G25,M25=$H25),8,IF(SIGN(L25-M25)=SIGN($G25-$H25),3,0))) -> 0 | Q25: =IF(OR(O25="",P25="",$G25="",$H25=""),0,IF(AND(O25=$G25,P25=$H25),8,IF(SIGN(O25-P25)=SIGN($G25-$H25),3,0))) -> 0 | T25: =IF(OR(R25="",S25="",$G25="",$H25=""),0,IF(AND(R25=$G25,S25=$H25),8,IF(SIGN(R25-S25)=SIGN($G25-$H25),3,0))) -> 0 | W25: =IF(OR(U25="",V25="",$G25="",$H25=""),0,IF(AND(U25=$G25,V25=$H25),8,IF(SIGN(U25-V25)=SIGN($G25-$H25),3,0))) -> 0 | X25: 3 | Y25: 1 | Z25: =IF(OR(X25="",Y25="",$G25="",$H25=""),0,IF(AND(X25=$G25,Y25=$H25),8,IF(SIGN(X25-Y25)=SIGN($G25-$H25),3,0))) -> 0 | AC25: =IF(OR(AA25="",AB25="",$G25="",$H25=""),0,IF(AND(AA25=$G25,AB25=$H25),8,IF(SIGN(AA25-AB25)=SIGN($G25-$H25),3,0))) -> 0 | AF25: =IF(OR(AD25="",AE25="",$G25="",$H25=""),0,IF(AND(AD25=$G25,AE25=$H25),8,IF(SIGN(AD25-AE25)=SIGN($G25-$H25),3,0))) -> 0 | AI25: =IF(OR(AG25="",AH25="",$G25="",$H25=""),0,IF(AND(AG25=$G25,AH25=$H25),8,IF(SIGN(AG25-AH25)=SIGN($G25-$H25),3,0))) -> 0
A26: 23 | B26: 46190 | C26: Group Stage | D26: L | E26: Ghana | F26: Panama | K26: =IF(OR(I26="",J26="",$G26="",$H26=""),0,IF(AND(I26=$G26,J26=$H26),8,IF(SIGN(I26-J26)=SIGN($G26-$H26),3,0))) -> 0 | N26: =IF(OR(L26="",M26="",$G26="",$H26=""),0,IF(AND(L26=$G26,M26=$H26),8,IF(SIGN(L26-M26)=SIGN($G26-$H26),3,0))) -> 0 | Q26: =IF(OR(O26="",P26="",$G26="",$H26=""),0,IF(AND(O26=$G26,P26=$H26),8,IF(SIGN(O26-P26)=SIGN($G26-$H26),3,0))) -> 0 | T26: =IF(OR(R26="",S26="",$G26="",$H26=""),0,IF(AND(R26=$G26,S26=$H26),8,IF(SIGN(R26-S26)=SIGN($G26-$H26),3,0))) -> 0 | W26: =IF(OR(U26="",V26="",$G26="",$H26=""),0,IF(AND(U26=$G26,V26=$H26),8,IF(SIGN(U26-V26)=SIGN($G26-$H26),3,0))) -> 0 | X26: 1 | Y26: 1 | Z26: =IF(OR(X26="",Y26="",$G26="",$H26=""),0,IF(AND(X26=$G26,Y26=$H26),8,IF(SIGN(X26-Y26)=SIGN($G26-$H26),3,0))) -> 0 | AC26: =IF(OR(AA26="",AB26="",$G26="",$H26=""),0,IF(AND(AA26=$G26,AB26=$H26),8,IF(SIGN(AA26-AB26)=SIGN($G26-$H26),3,0))) -> 0 | AF26: =IF(OR(AD26="",AE26="",$G26="",$H26=""),0,IF(AND(AD26=$G26,AE26=$H26),8,IF(SIGN(AD26-AE26)=SIGN($G26-$H26),3,0))) -> 0 | AI26: =IF(OR(AG26="",AH26="",$G26="",$H26=""),0,IF(AND(AG26=$G26,AH26=$H26),8,IF(SIGN(AG26-AH26)=SIGN($G26-$H26),3,0))) -> 0
A27: 24 | B27: 46190 | C27: Group Stage | D27: K | E27: Uzbekistan | F27: Colombia | K27: =IF(OR(I27="",J27="",$G27="",$H27=""),0,IF(AND(I27=$G27,J27=$H27),8,IF(SIGN(I27-J27)=SIGN($G27-$H27),3,0))) -> 0 | N27: =IF(OR(L27="",M27="",$G27="",$H27=""),0,IF(AND(L27=$G27,M27=$H27),8,IF(SIGN(L27-M27)=SIGN($G27-$H27),3,0))) -> 0 | Q27: =IF(OR(O27="",P27="",$G27="",$H27=""),0,IF(AND(O27=$G27,P27=$H27),8,IF(SIGN(O27-P27)=SIGN($G27-$H27),3,0))) -> 0 | T27: =IF(OR(R27="",S27="",$G27="",$H27=""),0,IF(AND(R27=$G27,S27=$H27),8,IF(SIGN(R27-S27)=SIGN($G27-$H27),3,0))) -> 0 | W27: =IF(OR(U27="",V27="",$G27="",$H27=""),0,IF(AND(U27=$G27,V27=$H27),8,IF(SIGN(U27-V27)=SIGN($G27-$H27),3,0))) -> 0 | X27: 0 | Y27: 2 | Z27: =IF(OR(X27="",Y27="",$G27="",$H27=""),0,IF(AND(X27=$G27,Y27=$H27),8,IF(SIGN(X27-Y27)=SIGN($G27-$H27),3,0))) -> 0 | AC27: =IF(OR(AA27="",AB27="",$G27="",$H27=""),0,IF(AND(AA27=$G27,AB27=$H27),8,IF(SIGN(AA27-AB27)=SIGN($G27-$H27),3,0))) -> 0 | AF27: =IF(OR(AD27="",AE27="",$G27="",$H27=""),0,IF(AND(AD27=$G27,AE27=$H27),8,IF(SIGN(AD27-AE27)=SIGN($G27-$H27),3,0))) -> 0 | AI27: =IF(OR(AG27="",AH27="",$G27="",$H27=""),0,IF(AND(AG27=$G27,AH27=$H27),8,IF(SIGN(AG27-AH27)=SIGN($G27-$H27),3,0))) -> 0
A28: 25 | B28: 46191 | C28: Group Stage | D28: A | E28: Czechia | F28: South Africa | K28: =IF(OR(I28="",J28="",$G28="",$H28=""),0,IF(AND(I28=$G28,J28=$H28),8,IF(SIGN(I28-J28)=SIGN($G28-$H28),3,0))) -> 0 | N28: =IF(OR(L28="",M28="",$G28="",$H28=""),0,IF(AND(L28=$G28,M28=$H28),8,IF(SIGN(L28-M28)=SIGN($G28-$H28),3,0))) -> 0 | Q28: =IF(OR(O28="",P28="",$G28="",$H28=""),0,IF(AND(O28=$G28,P28=$H28),8,IF(SIGN(O28-P28)=SIGN($G28-$H28),3,0))) -> 0 | T28: =IF(OR(R28="",S28="",$G28="",$H28=""),0,IF(AND(R28=$G28,S28=$H28),8,IF(SIGN(R28-S28)=SIGN($G28-$H28),3,0))) -> 0 | W28: =IF(OR(U28="",V28="",$G28="",$H28=""),0,IF(AND(U28=$G28,V28=$H28),8,IF(SIGN(U28-V28)=SIGN($G28-$H28),3,0))) -> 0 | X28: 0 | Y28: 0 | Z28: =IF(OR(X28="",Y28="",$G28="",$H28=""),0,IF(AND(X28=$G28,Y28=$H28),8,IF(SIGN(X28-Y28)=SIGN($G28-$H28),3,0))) -> 0 | AC28: =IF(OR(AA28="",AB28="",$G28="",$H28=""),0,IF(AND(AA28=$G28,AB28=$H28),8,IF(SIGN(AA28-AB28)=SIGN($G28-$H28),3,0))) -> 0 | AF28: =IF(OR(AD28="",AE28="",$G28="",$H28=""),0,IF(AND(AD28=$G28,AE28=$H28),8,IF(SIGN(AD28-AE28)=SIGN($G28-$H28),3,0))) -> 0 | AI28: =IF(OR(AG28="",AH28="",$G28="",$H28=""),0,IF(AND(AG28=$G28,AH28=$H28),8,IF(SIGN(AG28-AH28)=SIGN($G28-$H28),3,0))) -> 0
A29: 26 | B29: 46191 | C29: Group Stage | D29: B | E29: Switzerland | F29: Bosnia and Herzegovina | K29: =IF(OR(I29="",J29="",$G29="",$H29=""),0,IF(AND(I29=$G29,J29=$H29),8,IF(SIGN(I29-J29)=SIGN($G29-$H29),3,0))) -> 0 | N29: =IF(OR(L29="",M29="",$G29="",$H29=""),0,IF(AND(L29=$G29,M29=$H29),8,IF(SIGN(L29-M29)=SIGN($G29-$H29),3,0))) -> 0 | Q29: =IF(OR(O29="",P29="",$G29="",$H29=""),0,IF(AND(O29=$G29,P29=$H29),8,IF(SIGN(O29-P29)=SIGN($G29-$H29),3,0))) -> 0 | T29: =IF(OR(R29="",S29="",$G29="",$H29=""),0,IF(AND(R29=$G29,S29=$H29),8,IF(SIGN(R29-S29)=SIGN($G29-$H29),3,0))) -> 0 | W29: =IF(OR(U29="",V29="",$G29="",$H29=""),0,IF(AND(U29=$G29,V29=$H29),8,IF(SIGN(U29-V29)=SIGN($G29-$H29),3,0))) -> 0 | X29: 1 | Y29: 1 | Z29: =IF(OR(X29="",Y29="",$G29="",$H29=""),0,IF(AND(X29=$G29,Y29=$H29),8,IF(SIGN(X29-Y29)=SIGN($G29-$H29),3,0))) -> 0 | AC29: =IF(OR(AA29="",AB29="",$G29="",$H29=""),0,IF(AND(AA29=$G29,AB29=$H29),8,IF(SIGN(AA29-AB29)=SIGN($G29-$H29),3,0))) -> 0 | AF29: =IF(OR(AD29="",AE29="",$G29="",$H29=""),0,IF(AND(AD29=$G29,AE29=$H29),8,IF(SIGN(AD29-AE29)=SIGN($G29-$H29),3,0))) -> 0 | AI29: =IF(OR(AG29="",AH29="",$G29="",$H29=""),0,IF(AND(AG29=$G29,AH29=$H29),8,IF(SIGN(AG29-AH29)=SIGN($G29-$H29),3,0))) -> 0
A30: 27 | B30: 46191 | C30: Group Stage | D30: B | E30: Canada | F30: Qatar | K30: =IF(OR(I30="",J30="",$G30="",$H30=""),0,IF(AND(I30=$G30,J30=$H30),8,IF(SIGN(I30-J30)=SIGN($G30-$H30),3,0))) -> 0 | N30: =IF(OR(L30="",M30="",$G30="",$H30=""),0,IF(AND(L30=$G30,M30=$H30),8,IF(SIGN(L30-M30)=SIGN($G30-$H30),3,0))) -> 0 | Q30: =IF(OR(O30="",P30="",$G30="",$H30=""),0,IF(AND(O30=$G30,P30=$H30),8,IF(SIGN(O30-P30)=SIGN($G30-$H30),3,0))) -> 0 | T30: =IF(OR(R30="",S30="",$G30="",$H30=""),0,IF(AND(R30=$G30,S30=$H30),8,IF(SIGN(R30-S30)=SIGN($G30-$H30),3,0))) -> 0 | W30: =IF(OR(U30="",V30="",$G30="",$H30=""),0,IF(AND(U30=$G30,V30=$H30),8,IF(SIGN(U30-V30)=SIGN($G30-$H30),3,0))) -> 0 | X30: 2 | Y30: 1 | Z30: =IF(OR(X30="",Y30="",$G30="",$H30=""),0,IF(AND(X30=$G30,Y30=$H30),8,IF(SIGN(X30-Y30)=SIGN($G30-$H30),3,0))) -> 0 | AC30: =IF(OR(AA30="",AB30="",$G30="",$H30=""),0,IF(AND(AA30=$G30,AB30=$H30),8,IF(SIGN(AA30-AB30)=SIGN($G30-$H30),3,0))) -> 0 | AF30: =IF(OR(AD30="",AE30="",$G30="",$H30=""),0,IF(AND(AD30=$G30,AE30=$H30),8,IF(SIGN(AD30-AE30)=SIGN($G30-$H30),3,0))) -> 0 | AI30: =IF(OR(AG30="",AH30="",$G30="",$H30=""),0,IF(AND(AG30=$G30,AH30=$H30),8,IF(SIGN(AG30-AH30)=SIGN($G30-$H30),3,0))) -> 0
A31: 28 | B31: 46191 | C31: Group Stage | D31: A | E31: Mexico | F31: South Korea | K31: =IF(OR(I31="",J31="",$G31="",$H31=""),0,IF(AND(I31=$G31,J31=$H31),8,IF(SIGN(I31-J31)=SIGN($G31-$H31),3,0))) -> 0 | N31: =IF(OR(L31="",M31="",$G31="",$H31=""),0,IF(AND(L31=$G31,M31=$H31),8,IF(SIGN(L31-M31)=SIGN($G31-$H31),3,0))) -> 0 | Q31: =IF(OR(O31="",P31="",$G31="",$H31=""),0,IF(AND(O31=$G31,P31=$H31),8,IF(SIGN(O31-P31)=SIGN($G31-$H31),3,0))) -> 0 | T31: =IF(OR(R31="",S31="",$G31="",$H31=""),0,IF(AND(R31=$G31,S31=$H31),8,IF(SIGN(R31-S31)=SIGN($G31-$H31),3,0))) -> 0 | W31: =IF(OR(U31="",V31="",$G31="",$H31=""),0,IF(AND(U31=$G31,V31=$H31),8,IF(SIGN(U31-V31)=SIGN($G31-$H31),3,0))) -> 0 | X31: 2 | Y31: 2 | Z31: =IF(OR(X31="",Y31="",$G31="",$H31=""),0,IF(AND(X31=$G31,Y31=$H31),8,IF(SIGN(X31-Y31)=SIGN($G31-$H31),3,0))) -> 0 | AC31: =IF(OR(AA31="",AB31="",$G31="",$H31=""),0,IF(AND(AA31=$G31,AB31=$H31),8,IF(SIGN(AA31-AB31)=SIGN($G31-$H31),3,0))) -> 0 | AF31: =IF(OR(AD31="",AE31="",$G31="",$H31=""),0,IF(AND(AD31=$G31,AE31=$H31),8,IF(SIGN(AD31-AE31)=SIGN($G31-$H31),3,0))) -> 0 | AI31: =IF(OR(AG31="",AH31="",$G31="",$H31=""),0,IF(AND(AG31=$G31,AH31=$H31),8,IF(SIGN(AG31-AH31)=SIGN($G31-$H31),3,0))) -> 0
A32: 29 | B32: 46192 | C32: Group Stage | D32: D | E32: USA | F32: Australia | K32: =IF(OR(I32="",J32="",$G32="",$H32=""),0,IF(AND(I32=$G32,J32=$H32),8,IF(SIGN(I32-J32)=SIGN($G32-$H32),3,0))) -> 0 | N32: =IF(OR(L32="",M32="",$G32="",$H32=""),0,IF(AND(L32=$G32,M32=$H32),8,IF(SIGN(L32-M32)=SIGN($G32-$H32),3,0))) -> 0 | Q32: =IF(OR(O32="",P32="",$G32="",$H32=""),0,IF(AND(O32=$G32,P32=$H32),8,IF(SIGN(O32-P32)=SIGN($G32-$H32),3,0))) -> 0 | T32: =IF(OR(R32="",S32="",$G32="",$H32=""),0,IF(AND(R32=$G32,S32=$H32),8,IF(SIGN(R32-S32)=SIGN($G32-$H32),3,0))) -> 0 | W32: =IF(OR(U32="",V32="",$G32="",$H32=""),0,IF(AND(U32=$G32,V32=$H32),8,IF(SIGN(U32-V32)=SIGN($G32-$H32),3,0))) -> 0 | X32: 1 | Y32: 1 | Z32: =IF(OR(X32="",Y32="",$G32="",$H32=""),0,IF(AND(X32=$G32,Y32=$H32),8,IF(SIGN(X32-Y32)=SIGN($G32-$H32),3,0))) -> 0 | AC32: =IF(OR(AA32="",AB32="",$G32="",$H32=""),0,IF(AND(AA32=$G32,AB32=$H32),8,IF(SIGN(AA32-AB32)=SIGN($G32-$H32),3,0))) -> 0 | AF32: =IF(OR(AD32="",AE32="",$G32="",$H32=""),0,IF(AND(AD32=$G32,AE32=$H32),8,IF(SIGN(AD32-AE32)=SIGN($G32-$H32),3,0))) -> 0 | AI32: =IF(OR(AG32="",AH32="",$G32="",$H32=""),0,IF(AND(AG32=$G32,AH32=$H32),8,IF(SIGN(AG32-AH32)=SIGN($G32-$H32),3,0))) -> 0
A33: 30 | B33: 46192 | C33: Group Stage | D33: C | E33: Scotland | F33: Morocco | K33: =IF(OR(I33="",J33="",$G33="",$H33=""),0,IF(AND(I33=$G33,J33=$H33),8,IF(SIGN(I33-J33)=SIGN($G33-$H33),3,0))) -> 0 | N33: =IF(OR(L33="",M33="",$G33="",$H33=""),0,IF(AND(L33=$G33,M33=$H33),8,IF(SIGN(L33-M33)=SIGN($G33-$H33),3,0))) -> 0 | Q33: =IF(OR(O33="",P33="",$G33="",$H33=""),0,IF(AND(O33=$G33,P33=$H33),8,IF(SIGN(O33-P33)=SIGN($G33-$H33),3,0))) -> 0 | T33: =IF(OR(R33="",S33="",$G33="",$H33=""),0,IF(AND(R33=$G33,S33=$H33),8,IF(SIGN(R33-S33)=SIGN($G33-$H33),3,0))) -> 0 | W33: =IF(OR(U33="",V33="",$G33="",$H33=""),0,IF(AND(U33=$G33,V33=$H33),8,IF(SIGN(U33-V33)=SIGN($G33-$H33),3,0))) -> 0 | X33: 2 | Y33: 0 | Z33: =IF(OR(X33="",Y33="",$G33="",$H33=""),0,IF(AND(X33=$G33,Y33=$H33),8,IF(SIGN(X33-Y33)=SIGN($G33-$H33),3,0))) -> 0 | AC33: =IF(OR(AA33="",AB33="",$G33="",$H33=""),0,IF(AND(AA33=$G33,AB33=$H33),8,IF(SIGN(AA33-AB33)=SIGN($G33-$H33),3,0))) -> 0 | AF33: =IF(OR(AD33="",AE33="",$G33="",$H33=""),0,IF(AND(AD33=$G33,AE33=$H33),8,IF(SIGN(AD33-AE33)=SIGN($G33-$H33),3,0))) -> 0 | AI33: =IF(OR(AG33="",AH33="",$G33="",$H33=""),0,IF(AND(AG33=$G33,AH33=$H33),8,IF(SIGN(AG33-AH33)=SIGN($G33-$H33),3,0))) -> 0
A34: 31 | B34: 46192 | C34: Group Stage | D34: C | E34: Brazil | F34: Haiti | K34: =IF(OR(I34="",J34="",$G34="",$H34=""),0,IF(AND(I34=$G34,J34=$H34),8,IF(SIGN(I34-J34)=SIGN($G34-$H34),3,0))) -> 0 | N34: =IF(OR(L34="",M34="",$G34="",$H34=""),0,IF(AND(L34=$G34,M34=$H34),8,IF(SIGN(L34-M34)=SIGN($G34-$H34),3,0))) -> 0 | Q34: =IF(OR(O34="",P34="",$G34="",$H34=""),0,IF(AND(O34=$G34,P34=$H34),8,IF(SIGN(O34-P34)=SIGN($G34-$H34),3,0))) -> 0 | T34: =IF(OR(R34="",S34="",$G34="",$H34=""),0,IF(AND(R34=$G34,S34=$H34),8,IF(SIGN(R34-S34)=SIGN($G34-$H34),3,0))) -> 0 | W34: =IF(OR(U34="",V34="",$G34="",$H34=""),0,IF(AND(U34=$G34,V34=$H34),8,IF(SIGN(U34-V34)=SIGN($G34-$H34),3,0))) -> 0 | X34: 2 | Y34: 0 | Z34: =IF(OR(X34="",Y34="",$G34="",$H34=""),0,IF(AND(X34=$G34,Y34=$H34),8,IF(SIGN(X34-Y34)=SIGN($G34-$H34),3,0))) -> 0 | AC34: =IF(OR(AA34="",AB34="",$G34="",$H34=""),0,IF(AND(AA34=$G34,AB34=$H34),8,IF(SIGN(AA34-AB34)=SIGN($G34-$H34),3,0))) -> 0 | AF34: =IF(OR(AD34="",AE34="",$G34="",$H34=""),0,IF(AND(AD34=$G34,AE34=$H34),8,IF(SIGN(AD34-AE34)=SIGN($G34-$H34),3,0))) -> 0 | AI34: =IF(OR(AG34="",AH34="",$G34="",$H34=""),0,IF(AND(AG34=$G34,AH34=$H34),8,IF(SIGN(AG34-AH34)=SIGN($G34-$H34),3,0))) -> 0
... A75: 72 | B75: 46200 | C75: Group Stage | D75: J | E75: Algeria | F75: Austria | K75: =IF(OR(I75="",J75="",$G75="",$H75=""),0,IF(AND(I75=$G75,J75=$H75),8,IF(SIGN(I75-J75)=SIGN($G75-$H75),3,0))) -> 0 | N75: =IF(OR(L75="",M75="",$G75="",$H75=""),0,IF(AND(L75=$G75,M75=$H75),8,IF(SIGN(L75-M75)=SIGN($G75-$H75),3,0))) -> 0 | Q75: =IF(OR(O75="",P75="",$G75="",$H75=""),0,IF(AND(O75=$G75,P75=$H75),8,IF(SIGN(O75-P75)=SIGN($G75-$H75),3,0))) -> 0 | T75: =IF(OR(R75="",S75="",$G75="",$H75=""),0,IF(AND(R75=$G75,S75=$H75),8,IF(SIGN(R75-S75)=SIGN($G75-$H75),3,0))) -> 0 | W75: =IF(OR(U75="",V75="",$G75="",$H75=""),0,IF(AND(U75=$G75,V75=$H75),8,IF(SIGN(U75-V75)=SIGN($G75-$H75),3,0))) -> 0 | X75: 0 | Y75: 1 | Z75: =IF(OR(X75="",Y75="",$G75="",$H75=""),0,IF(AND(X75=$G75,Y75=$H75),8,IF(SIGN(X75-Y75)=SIGN($G75-$H75),3,0))) -> 0 | AC75: =IF(OR(AA75="",AB75="",$G75="",$H75=""),0,IF(AND(AA75=$G75,AB75=$H75),8,IF(SIGN(AA75-AB75)=SIGN($G75-$H75),3,0))) -> 0 | AF75: =IF(OR(AD75="",AE75="",$G75="",$H75=""),0,IF(AND(AD75=$G75,AE75=$H75),8,IF(SIGN(AD75-AE75)=SIGN($G75-$H75),3,0))) -> 0 | AI75: =IF(OR(AG75="",AH75="",$G75="",$H75=""),0,IF(AND(AG75=$G75,AH75=$H75),8,IF(SIGN(AG75-AH75)=SIGN($G75-$H75),3,0))) -> 0
A76: 73 | B76: 46201 | C76: Round of 32 | E76: Group A 2nd Place | F76: Group B 2nd Place | K76: =IF(OR(I76="",J76="",$G76="",$H76=""),0,IF(AND(I76=$G76,J76=$H76),8,IF(SIGN(I76-J76)=SIGN($G76-$H76),3,0))) -> 0 | N76: =IF(OR(L76="",M76="",$G76="",$H76=""),0,IF(AND(L76=$G76,M76=$H76),8,IF(SIGN(L76-M76)=SIGN($G76-$H76),3,0))) -> 0 | Q76: =IF(OR(O76="",P76="",$G76="",$H76=""),0,IF(AND(O76=$G76,P76=$H76),8,IF(SIGN(O76-P76)=SIGN($G76-$H76),3,0))) -> 0 | T76: =IF(OR(R76="",S76="",$G76="",$H76=""),0,IF(AND(R76=$G76,S76=$H76),8,IF(SIGN(R76-S76)=SIGN($G76-$H76),3,0))) -> 0 | W76: =IF(OR(U76="",V76="",$G76="",$H76=""),0,IF(AND(U76=$G76,V76=$H76),8,IF(SIGN(U76-V76)=SIGN($G76-$H76),3,0))) -> 0 | Z76: =IF(OR(X76="",Y76="",$G76="",$H76=""),0,IF(AND(X76=$G76,Y76=$H76),8,IF(SIGN(X76-Y76)=SIGN($G76-$H76),3,0))) -> 0 | AC76: =IF(OR(AA76="",AB76="",$G76="",$H76=""),0,IF(AND(AA76=$G76,AB76=$H76),8,IF(SIGN(AA76-AB76)=SIGN($G76-$H76),3,0))) -> 0 | AF76: =IF(OR(AD76="",AE76="",$G76="",$H76=""),0,IF(AND(AD76=$G76,AE76=$H76),8,IF(SIGN(AD76-AE76)=SIGN($G76-$H76),3,0))) -> 0 | AI76: =IF(OR(AG76="",AH76="",$G76="",$H76=""),0,IF(AND(AG76=$G76,AH76=$H76),8,IF(SIGN(AG76-AH76)=SIGN($G76-$H76),3,0))) -> 0
A77: 74 | B77: 46202 | C77: Round of 32 | E77: Group C Winner | F77: Group F 2nd Place | G77: 1 | H77: 1 | K77: =IF(OR(I77="",J77="",$G77="",$H77=""),0,IF(AND(I77=$G77,J77=$H77),8,IF(SIGN(I77-J77)=SIGN($G77-$H77),3,0))) -> 0 | N77: =IF(OR(L77="",M77="",$G77="",$H77=""),0,IF(AND(L77=$G77,M77=$H77),8,IF(SIGN(L77-M77)=SIGN($G77-$H77),3,0))) -> 0 | Q77: =IF(OR(O77="",P77="",$G77="",$H77=""),0,IF(AND(O77=$G77,P77=$H77),8,IF(SIGN(O77-P77)=SIGN($G77-$H77),3,0))) -> 0 | T77: =IF(OR(R77="",S77="",$G77="",$H77=""),0,IF(AND(R77=$G77,S77=$H77),8,IF(SIGN(R77-S77)=SIGN($G77-$H77),3,0))) -> 0 | W77: =IF(OR(U77="",V77="",$G77="",$H77=""),0,IF(AND(U77=$G77,V77=$H77),8,IF(SIGN(U77-V77)=SIGN($G77-$H77),3,0))) -> 0 | Z77: =IF(OR(X77="",Y77="",$G77="",$H77=""),0,IF(AND(X77=$G77,Y77=$H77),8,IF(SIGN(X77-Y77)=SIGN($G77-$H77),3,0))) -> 0 | AC77: =IF(OR(AA77="",AB77="",$G77="",$H77=""),0,IF(AND(AA77=$G77,AB77=$H77),8,IF(SIGN(AA77-AB77)=SIGN($G77-$H77),3,0))) -> 0 | AF77: =IF(OR(AD77="",AE77="",$G77="",$H77=""),0,IF(AND(AD77=$G77,AE77=$H77),8,IF(SIGN(AD77-AE77)=SIGN($G77-$H77),3,0))) -> 0 | AI77: =IF(OR(AG77="",AH77="",$G77="",$H77=""),0,IF(AND(AG77=$G77,AH77=$H77),8,IF(SIGN(AG77-AH77)=SIGN($G77-$H77),3,0))) -> 0 | AJ77: A
A78: 75 | B78: 46202 | C78: Round of 32 | E78: Group E Winner | F78: Group A/B/C/D/F 3rd Place | G78: 1 | H78: 1 | K78: =IF(OR(I78="",J78="",$G78="",$H78=""),0,IF(AND(I78=$G78,J78=$H78),8,IF(SIGN(I78-J78)=SIGN($G78-$H78),3,0))) -> 0 | N78: =IF(OR(L78="",M78="",$G78="",$H78=""),0,IF(AND(L78=$G78,M78=$H78),8,IF(SIGN(L78-M78)=SIGN($G78-$H78),3,0))) -> 0 | Q78: =IF(OR(O78="",P78="",$G78="",$H78=""),0,IF(AND(O78=$G78,P78=$H78),8,IF(SIGN(O78-P78)=SIGN($G78-$H78),3,0))) -> 0 | T78: =IF(OR(R78="",S78="",$G78="",$H78=""),0,IF(AND(R78=$G78,S78=$H78),8,IF(SIGN(R78-S78)=SIGN($G78-$H78),3,0))) -> 0 | W78: =IF(OR(U78="",V78="",$G78="",$H78=""),0,IF(AND(U78=$G78,V78=$H78),8,IF(SIGN(U78-V78)=SIGN($G78-$H78),3,0))) -> 0 | Z78: =IF(OR(X78="",Y78="",$G78="",$H78=""),0,IF(AND(X78=$G78,Y78=$H78),8,IF(SIGN(X78-Y78)=SIGN($G78-$H78),3,0))) -> 0 | AC78: =IF(OR(AA78="",AB78="",$G78="",$H78=""),0,IF(AND(AA78=$G78,AB78=$H78),8,IF(SIGN(AA78-AB78)=SIGN($G78-$H78),3,0))) -> 0 | AF78: =IF(OR(AD78="",AE78="",$G78="",$H78=""),0,IF(AND(AD78=$G78,AE78=$H78),8,IF(SIGN(AD78-AE78)=SIGN($G78-$H78),3,0))) -> 0 | AI78: =IF(OR(AG78="",AH78="",$G78="",$H78=""),0,IF(AND(AG78=$G78,AH78=$H78),8,IF(SIGN(AG78-AH78)=SIGN($G78-$H78),3,0))) -> 0 | AJ78: A
A79: 76 | B79: 46202 | C79: Round of 32 | E79: Group F Winner | F79: Group C 2nd Place | G79: 2 | H79: 1 | K79: =IF(OR(I79="",J79="",$G79="",$H79=""),0,IF(AND(I79=$G79,J79=$H79),8,IF(SIGN(I79-J79)=SIGN($G79-$H79),3,0))) -> 0 | N79: =IF(OR(L79="",M79="",$G79="",$H79=""),0,IF(AND(L79=$G79,M79=$H79),8,IF(SIGN(L79-M79)=SIGN($G79-$H79),3,0))) -> 0 | Q79: =IF(OR(O79="",P79="",$G79="",$H79=""),0,IF(AND(O79=$G79,P79=$H79),8,IF(SIGN(O79-P79)=SIGN($G79-$H79),3,0))) -> 0 | T79: =IF(OR(R79="",S79="",$G79="",$H79=""),0,IF(AND(R79=$G79,S79=$H79),8,IF(SIGN(R79-S79)=SIGN($G79-$H79),3,0))) -> 0 | W79: =IF(OR(U79="",V79="",$G79="",$H79=""),0,IF(AND(U79=$G79,V79=$H79),8,IF(SIGN(U79-V79)=SIGN($G79-$H79),3,0))) -> 0 | Z79: =IF(OR(X79="",Y79="",$G79="",$H79=""),0,IF(AND(X79=$G79,Y79=$H79),8,IF(SIGN(X79-Y79)=SIGN($G79-$H79),3,0))) -> 0 | AC79: =IF(OR(AA79="",AB79="",$G79="",$H79=""),0,IF(AND(AA79=$G79,AB79=$H79),8,IF(SIGN(AA79-AB79)=SIGN($G79-$H79),3,0))) -> 0 | AF79: =IF(OR(AD79="",AE79="",$G79="",$H79=""),0,IF(AND(AD79=$G79,AE79=$H79),8,IF(SIGN(AD79-AE79)=SIGN($G79-$H79),3,0))) -> 0 | AI79: =IF(OR(AG79="",AH79="",$G79="",$H79=""),0,IF(AND(AG79=$G79,AH79=$H79),8,IF(SIGN(AG79-AH79)=SIGN($G79-$H79),3,0))) -> 0
A80: 77 | B80: 46203 | C80: Round of 32 | E80: Group E 2nd Place | F80: Group I 2nd Place | K80: =IF(OR(I80="",J80="",$G80="",$H80=""),0,IF(AND(I80=$G80,J80=$H80),8,IF(SIGN(I80-J80)=SIGN($G80-$H80),3,0))) -> 0 | N80: =IF(OR(L80="",M80="",$G80="",$H80=""),0,IF(AND(L80=$G80,M80=$H80),8,IF(SIGN(L80-M80)=SIGN($G80-$H80),3,0))) -> 0 | Q80: =IF(OR(O80="",P80="",$G80="",$H80=""),0,IF(AND(O80=$G80,P80=$H80),8,IF(SIGN(O80-P80)=SIGN($G80-$H80),3,0))) -> 0 | T80: =IF(OR(R80="",S80="",$G80="",$H80=""),0,IF(AND(R80=$G80,S80=$H80),8,IF(SIGN(R80-S80)=SIGN($G80-$H80),3,0))) -> 0 | W80: =IF(OR(U80="",V80="",$G80="",$H80=""),0,IF(AND(U80=$G80,V80=$H80),8,IF(SIGN(U80-V80)=SIGN($G80-$H80),3,0))) -> 0 | Z80: =IF(OR(X80="",Y80="",$G80="",$H80=""),0,IF(AND(X80=$G80,Y80=$H80),8,IF(SIGN(X80-Y80)=SIGN($G80-$H80),3,0))) -> 0 | AC80: =IF(OR(AA80="",AB80="",$G80="",$H80=""),0,IF(AND(AA80=$G80,AB80=$H80),8,IF(SIGN(AA80-AB80)=SIGN($G80-$H80),3,0))) -> 0 | AF80: =IF(OR(AD80="",AE80="",$G80="",$H80=""),0,IF(AND(AD80=$G80,AE80=$H80),8,IF(SIGN(AD80-AE80)=SIGN($G80-$H80),3,0))) -> 0 | AI80: =IF(OR(AG80="",AH80="",$G80="",$H80=""),0,IF(AND(AG80=$G80,AH80=$H80),8,IF(SIGN(AG80-AH80)=SIGN($G80-$H80),3,0))) -> 0
...

Sheet Schedule
A1: 📅 FULL SCHEDULE — all 104 fixtures (kickoff times in ET)
A2: Match # | B2: Date | C2: Stage | D2: Group | E2: Home | F2: Away | G2: Venue | H2: Kickoff (ET)
A3: 1 | B3: 46184 | C3: Group Stage | D3: A | E3: Mexico | F3: South Africa | G3: Mexico City Stadium | H3: 3:00 PM ET
A4: 2 | B4: 46184 | C4: Group Stage | D4: A | E4: South Korea | F4: Czechia | G4: Guadalajara Stadium | H4: 10:00 PM ET
A5: 3 | B5: 46185 | C5: Group Stage | D5: B | E5: Canada | F5: Bosnia and Herzegovina | G5: Toronto Stadium | H5: 3:00 PM ET
A6: 4 | B6: 46185 | C6: Group Stage | D6: D | E6: USA | F6: Paraguay | G6: Los Angeles Stadium | H6: 9:00 PM ET
A7: 5 | B7: 46186 | C7: Group Stage | D7: B | E7: Qatar | F7: Switzerland | G7: San Francisco Bay Stadium | H7: 3:00 PM ET
A8: 6 | B8: 46186 | C8: Group Stage | D8: C | E8: Brazil | F8: Morocco | G8: New York New Jersey Stadium | H8: 6:00 PM ET
A9: 7 | B9: 46186 | C9: Group Stage | D9: C | E9: Haiti | F9: Scotland | G9: Boston Stadium | H9: 9:00 PM ET
A10: 8 | B10: 46186 | C10: Group Stage | D10: D | E10: Australia | F10: Türkiye | G10: BC Place Vancouver | H10: 12:00 AM ET
A11: 9 | B11: 46187 | C11: Group Stage | D11: E | E11: Germany | F11: Curaçao | G11: Houston Stadium | H11: 1:00 PM ET
A12: 10 | B12: 46187 | C12: Group Stage | D12: F | E12: Netherlands | F12: Japan | G12: Dallas Stadium | H12: 4:00 PM ET
A13: 11 | B13: 46187 | C13: Group Stage | D13: E | E13: Ivory Coast | F13: Ecuador | G13: Philadelphia Stadium | H13: 7:00 PM ET
A14: 12 | B14: 46187 | C14: Group Stage | D14: F | E14: Tunisia | F14: Sweden | G14: Monterrey Stadium | H14: 10:00 PM ET
... A74: 72 | B74: 46200 | C74: Group Stage | D74: J | E74: Algeria | F74: Austria | G74: Kansas City Stadium | H74: 10:00 PM ET
A75: 73 | B75: 46201 | C75: Round of 32 | E75: Group A 2nd Place | F75: Group B 2nd Place | G75: Los Angeles Stadium | H75: 3:00 PM ET
A76: 74 | B76: 46202 | C76: Round of 32 | E76: Group C Winner | F76: Group F 2nd Place | G76: Houston Stadium | H76: 1:00 PM ET
A77: 75 | B77: 46202 | C77: Round of 32 | E77: Group E Winner | F77: Group A/B/C/D/F 3rd Place | G77: Boston Stadium | H77: 4:30 PM ET
A78: 76 | B78: 46202 | C78: Round of 32 | E78: Group F Winner | F78: Group C 2nd Place | G78: Monterrey Stadium | H78: 9:00 PM ET
A79: 77 | B79: 46203 | C79: Round of 32 | E79: Group E 2nd Place | F79: Group I 2nd Place | G79: Dallas Stadium | H79: 1:00 PM ET
A80: 78 | B80: 46203 | C80: Round of 32 | E80: Group I Winner | F80: Group C/D/F/G/H 3rd Place | G80: New York New Jersey Stadium | H80: 5:00 PM ET
A81: 79 | B81: 46203 | C81: Round of 32 | E81: Group A Winner | F81: Group C/E/F/H/I 3rd Place | G81: Mexico City Stadium | H81: 9:00 PM ET
A82: 80 | B82: 46204 | C82: Round of 32 | E82: Group L Winner | F82: Group E/H/I/J/K 3rd Place | G82: Atlanta Stadium | H82: 12:00 PM ET
A83: 81 | B83: 46204 | C83: Round of 32 | E83: Group G Winner | F83: Group A/E/H/I/J 3rd Place | G83: Seattle Stadium | H83: 4:00 PM ET
A84: 82 | B84: 46204 | C84: Round of 32 | E84: Group D Winner | F84: Group B/E/F/I/J 3rd Place | G84: San Francisco Bay Stadium | H84: 8:00 PM ET
A85: 83 | B85: 46205 | C85: Round of 32 | E85: Group H Winner | F85: Group J 2nd Place | G85: Los Angeles Stadium | H85: 3:00 PM ET
A86: 84 | B86: 46205 | C86: Round of 32 | E86: Group K 2nd Place | F86: Group L 2nd Place | G86: Toronto Stadium | H86: 7:00 PM ET
... A106: 104 | B106: 46222 | C106: Final | E106: Winner Match 101 | F106: Winner Match 102 | G106: New York New Jersey Stadium | H106: 3:00 PM ET

Sheet Tournament Picks
A1: 🏆 PRE-TOURNAMENT PICKS — Champion 25 · Runner-Up 15 · Semifinalists 10 each (max 80)
B3: ACTUAL RESULTS — fill in as each stage is reached:
B4: Champion
B5: Runner-Up
B6: Semifinalists (all 4)
A8: Player | B8: Champion | C8: Runner-Up | D8: SF 1 | E8: SF 2 | F8: SF 3 | G8: SF 4 | H8: Champ | I8: R-Up | J8: SFs | K8: Total
A9: ='Match Predictions'!I2 -> Ewan | B9: Spain | H9: =IF(AND(B9<>"",B9=$C$4),25,0) -> 0 | I9: =IF(AND(C9<>"",C9=$C$5),15,0) -> 0 | J9: =IF(AND(D9<>"",COUNTIF($C$6:$F$6,D9)>0),10,0)+IF(AND(E9<>"",COUNTIF($C$6:$F$6,E9)>0),10,0)+IF(AND(F9<>"",COUNTIF($C$6:$F$6,F9)>0),10,0)+IF(AND(G9<>"",COUNTIF($C$6:$F$6,G9)>0),10,0) -> 0 | K9: =SUM(H9:J9) -> 0
A10: ='Match Predictions'!L2 -> Nana | B10: France | H10: =IF(AND(B10<>"",B10=$C$4),25,0) -> 0 | I10: =IF(AND(C10<>"",C10=$C$5),15,0) -> 0 | J10: =IF(AND(D10<>"",COUNTIF($C$6:$F$6,D10)>0),10,0)+IF(AND(E10<>"",COUNTIF($C$6:$F$6,E10)>0),10,0)+IF(AND(F10<>"",COUNTIF($C$6:$F$6,F10)>0),10,0)+IF(AND(G10<>"",COUNTIF($C$6:$F$6,G10)>0),10,0) -> 0 | K10: =SUM(H10:J10) -> 0
A11: ='Match Predictions'!O2 -> Emrys | H11: =IF(AND(B11<>"",B11=$C$4),25,0) -> 0 | I11: =IF(AND(C11<>"",C11=$C$5),15,0) -> 0 | J11: =IF(AND(D11<>"",COUNTIF($C$6:$F$6,D11)>0),10,0)+IF(AND(E11<>"",COUNTIF($C$6:$F$6,E11)>0),10,0)+IF(AND(F11<>"",COUNTIF($C$6:$F$6,F11)>0),10,0)+IF(AND(G11<>"",COUNTIF($C$6:$F$6,G11)>0),10,0) -> 0 | K11: =SUM(H11:J11) -> 0
A12: ='Match Predictions'!R2 -> Nonno | B12: Brazil | H12: =IF(AND(B12<>"",B12=$C$4),25,0) -> 0 | I12: =IF(AND(C12<>"",C12=$C$5),15,0) -> 0 | J12: =IF(AND(D12<>"",COUNTIF($C$6:$F$6,D12)>0),10,0)+IF(AND(E12<>"",COUNTIF($C$6:$F$6,E12)>0),10,0)+IF(AND(F12<>"",COUNTIF($C$6:$F$6,F12)>0),10,0)+IF(AND(G12<>"",COUNTIF($C$6:$F$6,G12)>0),10,0) -> 0 | K12: =SUM(H12:J12) -> 0
A13: ='Match Predictions'!U2 -> Nonna | H13: =IF(AND(B13<>"",B13=$C$4),25,0) -> 0 | I13: =IF(AND(C13<>"",C13=$C$5),15,0) -> 0 | J13: =IF(AND(D13<>"",COUNTIF($C$6:$F$6,D13)>0),10,0)+IF(AND(E13<>"",COUNTIF($C$6:$F$6,E13)>0),10,0)+IF(AND(F13<>"",COUNTIF($C$6:$F$6,F13)>0),10,0)+IF(AND(G13<>"",COUNTIF($C$6:$F$6,G13)>0),10,0) -> 0 | K13: =SUM(H13:J13) -> 0
A14: ='Match Predictions'!X2 -> Boompa | B14: France | H14: =IF(AND(B14<>"",B14=$C$4),25,0) -> 0 | I14: =IF(AND(C14<>"",C14=$C$5),15,0) -> 0 | J14: =IF(AND(D14<>"",COUNTIF($C$6:$F$6,D14)>0),10,0)+IF(AND(E14<>"",COUNTIF($C$6:$F$6,E14)>0),10,0)+IF(AND(F14<>"",COUNTIF($C$6:$F$6,F14)>0),10,0)+IF(AND(G14<>"",COUNTIF($C$6:$F$6,G14)>0),10,0) -> 0 | K14: =SUM(H14:J14) -> 0
A15: ='Match Predictions'!AA2 -> Xavier | H15: =IF(AND(B15<>"",B15=$C$4),25,0) -> 0 | I15: =IF(AND(C15<>"",C15=$C$5),15,0) -> 0 | J15: =IF(AND(D15<>"",COUNTIF($C$6:$F$6,D15)>0),10,0)+IF(AND(E15<>"",COUNTIF($C$6:$F$6,E15)>0),10,0)+IF(AND(F15<>"",COUNTIF($C$6:$F$6,F15)>0),10,0)+IF(AND(G15<>"",COUNTIF($C$6:$F$6,G15)>0),10,0) -> 0 | K15: =SUM(H15:J15) -> 0
A16: ='Match Predictions'!AD2 -> Autumn | H16: =IF(AND(B16<>"",B16=$C$4),25,0) -> 0 | I16: =IF(AND(C16<>"",C16=$C$5),15,0) -> 0 | J16: =IF(AND(D16<>"",COUNTIF($C$6:$F$6,D16)>0),10,0)+IF(AND(E16<>"",COUNTIF($C$6:$F$6,E16)>0),10,0)+IF(AND(F16<>"",COUNTIF($C$6:$F$6,F16)>0),10,0)+IF(AND(G16<>"",COUNTIF($C$6:$F$6,G16)>0),10,0) -> 0 | K16: =SUM(H16:J16) -> 0
A17: ='Match Predictions'!AG2 -> River | H17: =IF(AND(B17<>"",B17=$C$4),25,0) -> 0 | I17: =IF(AND(C17<>"",C17=$C$5),15,0) -> 0 | J17: =IF(AND(D17<>"",COUNTIF($C$6:$F$6,D17)>0),10,0)+IF(AND(E17<>"",COUNTIF($C$6:$F$6,E17)>0),10,0)+IF(AND(F17<>"",COUNTIF($C$6:$F$6,F17)>0),10,0)+IF(AND(G17<>"",COUNTIF($C$6:$F$6,G17)>0),10,0) -> 0 | K17: =SUM(H17:J17) -> 0

Sheet Leaderboard
A1: 🏆 LEADERBOARD
A2: Updates automatically. Sort by the TOTAL column (Largest to Smallest) or read the Rank column.
A3: Rank | B3: Player | C3: Pre-Tourney | D3: Match Pts | E3: TOTAL | F3: Exact Scores | G3: Correct Picks | H3: Accuracy | I3: Champion Pick
A4: =RANK(E4,$E$4:$E$12) -> 3 | B4: ='Match Predictions'!I2 -> Ewan | C4: ='Tournament Picks'!K9 -> 0 | D4: =SUM('Match Predictions'!K4:K107) -> 14 | E4: =C4+D4 -> 14 | F4: =COUNTIF('Match Predictions'!K4:K107,8) -> 1 | G4: =COUNTIF('Match Predictions'!K4:K107,">=3") -> 3 | H4: =IF(SUMPRODUCT(('Match Predictions'!I4:I107<>"")*('Match Predictions'!$G$4:$G$107<>""))=0,"",G4/SUMPRODUCT(('Match Predictions'!I4:I107<>"")*('Match Predictions'!$G$4:$G$107<>""))) -> 0.75 | I4: ='Tournament Picks'!B9 -> Spain
A5: =RANK(E5,$E$4:$E$12) -> 3 | B5: ='Match Predictions'!L2 -> Nana | C5: ='Tournament Picks'!K10 -> 0 | D5: =SUM('Match Predictions'!N4:N107) -> 14 | E5: =C5+D5 -> 14 | F5: =COUNTIF('Match Predictions'!N4:N107,8) -> 1 | G5: =COUNTIF('Match Predictions'!N4:N107,">=3") -> 3 | H5: =IF(SUMPRODUCT(('Match Predictions'!L4:L107<>"")*('Match Predictions'!$G$4:$G$107<>""))=0,"",G5/SUMPRODUCT(('Match Predictions'!L4:L107<>"")*('Match Predictions'!$G$4:$G$107<>""))) -> 0.75 | I5: ='Tournament Picks'!B10 -> France
A6: =RANK(E6,$E$4:$E$12) -> 6 | B6: ='Match Predictions'!O2 -> Emrys | C6: ='Tournament Picks'!K11 -> 0 | D6: =SUM('Match Predictions'!Q4:Q107) -> 9 | E6: =C6+D6 -> 9 | F6: =COUNTIF('Match Predictions'!Q4:Q107,8) -> 0 | G6: =COUNTIF('Match Predictions'!Q4:Q107,">=3") -> 3 | H6: =IF(SUMPRODUCT(('Match Predictions'!O4:O107<>"")*('Match Predictions'!$G$4:$G$107<>""))=0,"",G6/SUMPRODUCT(('Match Predictions'!O4:O107<>"")*('Match Predictions'!$G$4:$G$107<>""))) -> 0.75 | I6: ='Tournament Picks'!B11 -> 0
A7: =RANK(E7,$E$4:$E$12) -> 3 | B7: ='Match Predictions'!R2 -> Nonno | C7: ='Tournament Picks'!K12 -> 0 | D7: =SUM('Match Predictions'!T4:T107) -> 14 | E7: =C7+D7 -> 14 | F7: =COUNTIF('Match Predictions'!T4:T107,8) -> 1 | G7: =COUNTIF('Match Predictions'!T4:T107,">=3") -> 3 | H7: =IF(SUMPRODUCT(('Match Predictions'!R4:R107<>"")*('Match Predictions'!$G$4:$G$107<>""))=0,"",G7/SUMPRODUCT(('Match Predictions'!R4:R107<>"")*('Match Predictions'!$G$4:$G$107<>""))) -> 0.75 | I7: ='Tournament Picks'!B12 -> Brazil
A8: =RANK(E8,$E$4:$E$12) -> 1 | B8: ='Match Predictions'!U2 -> Nonna | C8: ='Tournament Picks'!K13 -> 0 | D8: =SUM('Match Predictions'!W4:W107) -> 30 | E8: =C8+D8 -> 30 | F8: =COUNTIF('Match Predictions'!W4:W107,8) -> 3 | G8: =COUNTIF('Match Predictions'!W4:W107,">=3") -> 5 | H8: =IF(SUMPRODUCT(('Match Predictions'!U4:U107<>"")*('Match Predictions'!$G$4:$G$107<>""))=0,"",G8/SUMPRODUCT(('Match Predictions'!U4:U107<>"")*('Match Predictions'!$G$4:$G$107<>""))) -> 0.83333333 | I8: ='Tournament Picks'!B13 -> 0
A9: =RANK(E9,$E$4:$E$12) -> 9 | B9: ='Match Predictions'!X2 -> Boompa | C9: ='Tournament Picks'!K14 -> 0 | D9: =SUM('Match Predictions'!Z4:Z107) -> 0 | E9: =C9+D9 -> 0 | F9: =COUNTIF('Match Predictions'!Z4:Z107,8) -> 0 | G9: =COUNTIF('Match Predictions'!Z4:Z107,">=3") -> 0 | H9: =IF(SUMPRODUCT(('Match Predictions'!X4:X107<>"")*('Match Predictions'!$G$4:$G$107<>""))=0,"",G9/SUMPRODUCT(('Match Predictions'!X4:X107<>"")*('Match Predictions'!$G$4:$G$107<>""))) -> 0 | I9: ='Tournament Picks'!B14 -> France
A10: =RANK(E10,$E$4:$E$12) -> 2 | B10: ='Match Predictions'!AA2 -> Xavier | C10: ='Tournament Picks'!K15 -> 0 | D10: =SUM('Match Predictions'!AC4:AC107) -> 27 | E10: =C10+D10 -> 27 | F10: =COUNTIF('Match Predictions'!AC4:AC107,8) -> 3 | G10: =COUNTIF('Match Predictions'!AC4:AC107,">=3") -> 4 | H10: =IF(SUMPRODUCT(('Match Predictions'!AA4:AA107<>"")*('Match Predictions'!$G$4:$G$107<>""))=0,"",G10/SUMPRODUCT(('Match Predictions'!AA4:AA107<>"")*('Match Predictions'!$G$4:$G$107<>""))) -> 1 | I10: ='Tournament Picks'!B15 -> 0
A11: =RANK(E11,$E$4:$E$12) -> 7 | B11: ='Match Predictions'!AD2 -> Autumn | C11: ='Tournament Picks'!K16 -> 0 | D11: =SUM('Match Predictions'!AF4:AF107) -> 8 | E11: =C11+D11 -> 8 | F11: =COUNTIF('Match Predictions'!AF4:AF107,8) -> 1 | G11: =COUNTIF('Match Predictions'!AF4:AF107,">=3") -> 1 | H11: =IF(SUMPRODUCT(('Match Predictions'!AD4:AD107<>"")*('Match Predictions'!$G$4:$G$107<>""))=0,"",G11/SUMPRODUCT(('Match Predictions'!AD4:AD107<>"")*('Match Predictions'!$G$4:$G$107<>""))) -> 0.25 | I11: ='Tournament Picks'!B16 -> 0
A12: =RANK(E12,$E$4:$E$12) -> 8 | B12: ='Match Predictions'!AG2 -> River | C12: ='Tournament Picks'!K17 -> 0 | D12: =SUM('Match Predictions'!AI4:AI107) -> 6 | E12: =C12+D12 -> 6 | F12: =COUNTIF('Match Predictions'!AI4:AI107,8) -> 0 | G12: =COUNTIF('Match Predictions'!AI4:AI107,">=3") -> 2 | H12: =IF(SUMPRODUCT(('Match Predictions'!AG4:AG107<>"")*('Match Predictions'!$G$4:$G$107<>""))=0,"",G12/SUMPRODUCT(('Match Predictions'!AG4:AG107<>"")*('Match Predictions'!$G$4:$G$107<>""))) -> 0.5 | I12: ='Tournament Picks'!B17 -> 0
